Workbook

Sheet MASTER DATA
B1: DASHBOARD TARGET KEUANGAN — MASTER DATA & PENGATURAN PERIODE
B2: ⚙ PENGATURAN PERIODE | C2: Bulan (1-12): | D2: 4 | E2: Tahun: | F2: 2026 | G2: Periode Aktif: | H2: =UPPER(TEXT(DATE(F2,D2,1),"MMMM YYYY")) | I2: =DAY(EOMONTH(DATE(F2,D2,1),0))
B3: Ganti D2 (Bulan) & F2 (Tahun) → semua sheet update otomatis | Biru = input | Hitam = formula | *Target Harian Manual: isi untuk override, kosongkan untuk auto (Bulanan÷Hari Kerja) | 🟢 Kolom L: Pilih "Kuantitatif" atau "Kualitatif" | Kolom M: Isi deskripsi target jika Kualitatif
B4: No | C4: Program | D4: PIC | E4: Target Bulanan (Rp) | F4: Target Bulanan (User) | G4: Hari Kerja* | H4: Target Harian Manual (Rp) [opsional] | I4: Target Harian Manual (User) [opsional] | J4: Target Harian Efektif (Rp) | K4: Target Harian Efektif (User) | L4: Tipe Target (Kuantitatif/ Kualitatif) | M4: Target Kualitatif (Isi jika Tipe = Kualitatif)
B5: 1 | C5: Kelas Pelatihan & Sertifikasi Asosiasi | D5: RHJ | E5: 150000000 | F5: 300 | G5: =$I$2 | J5: =IFERROR(IF(C5="","",IF(H5<>"",H5,E5/G5)),0) | K5: =IFERROR(IF(C5="","",IF(I5<>"",I5,F5/G5)),0) | L5: Kuantitatif
B6: 2 | C6: Kelas Pelatihan & Sertifikasi BNSP | D6: RHJ | E6: 100000000 | F6: 100 | G6: =$I$2 | J6: =IFERROR(IF(C6="","",IF(H6<>"",H6,E6/G6)),0) | K6: =IFERROR(IF(C6="","",IF(I6<>"",I6,F6/G6)),0) | L6: Kuantitatif
B7: 3 | C7: Kelas Public Speaking Pedagogik | D7: ANDIS | E7: 50000000 | F7: 50 | G7: =$I$2 | J7: =IFERROR(IF(C7="","",IF(H7<>"",H7,E7/G7)),0) | K7: =IFERROR(IF(C7="","",IF(I7<>"",I7,F7/G7)),0) | L7: Kuantitatif
B8: 4 | C8: Kelas Kerjasama Perguruan Tinggi (SKPI) | D8: PROF | E8: 50000000 | F8: 50 | G8: =$I$2 | J8: =IFERROR(IF(C8="","",IF(H8<>"",H8,E8/G8)),0) | K8: =IFERROR(IF(C8="","",IF(I8<>"",I8,F8/G8)),0) | L8: Kuantitatif
B9: 5 | C9: Kelas Pelatihan & Sertifikasi Asosiasi & BNSP (Offline) | D9: ANGGAR | E9: 25000000 | F9: 25 | G9: =$I$2 | J9: =IFERROR(IF(C9="","",IF(H9<>"",H9,E9/G9)),0) | K9: =IFERROR(IF(C9="","",IF(I9<>"",I9,F9/G9)),0) | L9: Kuantitatif
B10: 6 | C10: Kerjasama Dengan LPK / LK | D10: ANGGAR | E10: 25000000 | F10: 5 | G10: =$I$2 | J10: =IFERROR(IF(C10="","",IF(H10<>"",H10,E10/G10)),0) | K10: =IFERROR(IF(C10="","",IF(I10<>"",I10,F10/G10)),0) | L10: Kuantitatif
B11: 7 | C11: Sertifikasi SMK | D11: EKO | E11: 50000000 | F11: 100 | G11: =$I$2 | J11: =IFERROR(IF(C11="","",IF(H11<>"",H11,E11/G11)),0) | K11: =IFERROR(IF(C11="","",IF(I11<>"",I11,F11/G11)),0) | L11: Kuantitatif
B12: 8 | C12: TES PROJECT | D12: TES | E12: 10000000 | F12: 40 | G12: =$I$2 | J12: =IFERROR(IF(C12="","",IF(H12<>"",H12,E12/G12)),0) | K12: =IFERROR(IF(C12="","",IF(I12<>"",I12,F12/G12)),0) | L12: Kuantitatif
B13: 9 | G13: =$I$2 | J13: =IFERROR(IF(C13="","",IF(H13<>"",H13,E13/G13)),0) | K13: =IFERROR(IF(C13="","",IF(I13<>"",I13,F13/G13)),0)
B14: 10 | G14: =$I$2 | J14: =IFERROR(IF(C14="","",IF(H14<>"",H14,E14/G14)),0) | K14: =IFERROR(IF(C14="","",IF(I14<>"",I14,F14/G14)),0)
B15: 11 | G15: =$I$2 | J15: =IFERROR(IF(C15="","",IF(H15<>"",H15,E15/G15)),0) | K15: =IFERROR(IF(C15="","",IF(I15<>"",I15,F15/G15)),0)
B16: 12 | G16: =$I$2 | J16: =IFERROR(IF(C16="","",IF(H16<>"",H16,E16/G16)),0) | K16: =IFERROR(IF(C16="","",IF(I16<>"",I16,F16/G16)),0)
B17: 13 | G17: =$I$2 | J17: =IFERROR(IF(C17="","",IF(H17<>"",H17,E17/G17)),0) | K17: =IFERROR(IF(C17="","",IF(I17<>"",I17,F17/G17)),0)
B18: 14 | G18: =$I$2 | J18: =IFERROR(IF(C18="","",IF(H18<>"",H18,E18/G18)),0) | K18: =IFERROR(IF(C18="","",IF(I18<>"",I18,F18/G18)),0)
B19: 15 | G19: =$I$2 | J19: =IFERROR(IF(C19="","",IF(H19<>"",H19,E19/G19)),0) | K19: =IFERROR(IF(C19="","",IF(I19<>"",I19,F19/G19)),0)
B20: TOTAL KESELURUHAN | E20: =SUM(E5:E19) | F20: =SUM(F5:F19) | J20: =SUM(J5:J19) | K20: =SUM(K5:K19)
B21: * Hari Kerja default = jumlah hari bulan aktif (auto). Kolom merah muda (Target Harian Manual): isi angka untuk override, kosongkan = auto dari Target Bulanan ÷ Hari Kerja.

Sheet INPUT HARIAN
B1: =UPPER("INPUT PENCAPAIAN HARIAN — "&'MASTER DATA'!H2)
B2: Isi kolom BIRU | Tanggal: ketik langsung (format MM/DD/YYYY) atau pilih dari kalender | PIC otomatis terisi | Kolom I: Isi Status Kualitatif ("Belum" / "Sedang Proses" / "Selesai") untuk program bertipe Kualitatif
B3: No | C3: Tanggal | D3: Program | E3: PIC | F3: Pencapaian (Rp) | G3: Pencapaian (User) | H3: Catatan / Keterangan | I3: Status Kualitatif (Isi jika program Kualitatif)
B4: 1 | C4: 46113 | D4: Kelas Pelatihan & Sertifikasi Asosiasi | E4: =IFERROR(IF(D4="","",VLOOKUP(D4,'MASTER DATA'!C5:D19,2,0)),"") | F4: 3835000 | G4: 8
B5: 2 | C5: 46118 | D5: TES PROJECT | E5: =IFERROR(IF(D5="","",VLOOKUP(D5,'MASTER DATA'!C5:D19,2,0)),"") | F5: 500000 | G5: 12
B6: 3 | C6: 46117 | D6: TES PROJECT | E6: =IFERROR(IF(D6="","",VLOOKUP(D6,'MASTER DATA'!C5:D19,2,0)),"") | F6: 200000 | G6: 4
B7: 4 | E7: =IFERROR(IF(D7="","",VLOOKUP(D7,'MASTER DATA'!C5:D19,2,0)),"")
B8: 5 | E8: =IFERROR(IF(D8="","",VLOOKUP(D8,'MASTER DATA'!C5:D19,2,0)),"")
B9: 6 | E9: =IFERROR(IF(D9="","",VLOOKUP(D9,'MASTER DATA'!C5:D19,2,0)),"")
B10: 7 | E10: =IFERROR(IF(D10="","",VLOOKUP(D10,'MASTER DATA'!C5:D19,2,0)),"")
B11: 8 | E11: =IFERROR(IF(D11="","",VLOOKUP(D11,'MASTER DATA'!C5:D19,2,0)),"")
B12: 9 | E12: =IFERROR(IF(D12="","",VLOOKUP(D12,'MASTER DATA'!C5:D19,2,0)),"")
B13: 10 | E13: =IFERROR(IF(D13="","",VLOOKUP(D13,'MASTER DATA'!C5:D19,2,0)),"")
B14: 11 | E14: =IFERROR(IF(D14="","",VLOOKUP(D14,'MASTER DATA'!C5:D19,2,0)),"")
B15: 12 | E15: =IFERROR(IF(D15="","",VLOOKUP(D15,'MASTER DATA'!C5:D19,2,0)),"")
B16: 13 | E16: =IFERROR(IF(D16="","",VLOOKUP(D16,'MASTER DATA'!C5:D19,2,0)),"")
B17: 14 | E17: =IFERROR(IF(D17="","",VLOOKUP(D17,'MASTER DATA'!C5:D19,2,0)),"")
B18: 15 | E18: =IFERROR(IF(D18="","",VLOOKUP(D18,'MASTER DATA'!C5:D19,2,0)),"")
B19: 16 | E19: =IFERROR(IF(D19="","",VLOOKUP(D19,'MASTER DATA'!C5:D19,2,0)),"")
B20: 17 | E20: =IFERROR(IF(D20="","",VLOOKUP(D20,'MASTER DATA'!C5:D19,2,0)),"")
B21: 18 | E21: =IFERROR(IF(D21="","",VLOOKUP(D21,'MASTER DATA'!C5:D19,2,0)),"")
B22: 19 | E22: =IFERROR(IF(D22="","",VLOOKUP(D22,'MASTER DATA'!C5:D19,2,0)),"")
B23: 20 | E23: =IFERROR(IF(D23="","",VLOOKUP(D23,'MASTER DATA'!C5:D19,2,0)),"")
B24: 21 | E24: =IFERROR(IF(D24="","",VLOOKUP(D24,'MASTER DATA'!C5:D19,2,0)),"")
B25: 22 | E25: =IFERROR(IF(D25="","",VLOOKUP(D25,'MASTER DATA'!C5:D19,2,0)),"")
B26: 23 | E26: =IFERROR(IF(D26="","",VLOOKUP(D26,'MASTER DATA'!C5:D19,2,0)),"")
B27: 24 | E27: =IFERROR(IF(D27="","",VLOOKUP(D27,'MASTER DATA'!C5:D19,2,0)),"")
B28: 25 | E28: =IFERROR(IF(D28="","",VLOOKUP(D28,'MASTER DATA'!C5:D19,2,0)),"")
B29: 26 | E29: =IFERROR(IF(D29="","",VLOOKUP(D29,'MASTER DATA'!C5:D19,2,0)),"")
B30: 27 | E30: =IFERROR(IF(D30="","",VLOOKUP(D30,'MASTER DATA'!C5:D19,2,0)),"")
B31: 28 | E31: =IFERROR(IF(D31="","",VLOOKUP(D31,'MASTER DATA'!C5:D19,2,0)),"")
B32: 29 | E32: =IFERROR(IF(D32="","",VLOOKUP(D32,'MASTER DATA'!C5:D19,2,0)),"")
B33: 30 | E33: =IFERROR(IF(D33="","",VLOOKUP(D33,'MASTER DATA'!C5:D19,2,0)),"")
B34: 31 | E34: =IFERROR(IF(D34="","",VLOOKUP(D34,'MASTER DATA'!C5:D19,2,0)),"")
B35: 32 | E35: =IFERROR(IF(D35="","",VLOOKUP(D35,'MASTER DATA'!C5:D19,2,0)),"")
B36: 33 | E36: =IFERROR(IF(D36="","",VLOOKUP(D36,'MASTER DATA'!C5:D19,2,0)),"")
B37: 34 | E37: =IFERROR(IF(D37="","",VLOOKUP(D37,'MASTER DATA'!C5:D19,2,0)),"")
B38: 35 | E38: =IFERROR(IF(D38="","",VLOOKUP(D38,'MASTER DATA'!C5:D19,2,0)),"")
B39: 36 | E39: =IFERROR(IF(D39="","",VLOOKUP(D39,'MASTER DATA'!C5:D19,2,0)),"")
B40: 37 | E40: =IFERROR(IF(D40="","",VLOOKUP(D40,'MASTER DATA'!C5:D19,2,0)),"")
...

Sheet DASHBOARD BULANAN
B1: ="DASHBOARD BULANAN — "&'MASTER DATA'!H2
B2: Data diambil otomatis dari INPUT HARIAN. Ganti bulan di sheet MASTER DATA → dashboard langsung update.
B3: 📊 PENCAPAIAN DALAM SATUAN RUPIAH (Rp)
B4: No | C4: Program | D4: PIC | E4: Target Bulanan | F4: Pencapaian | G4: % Capaian | H4: Sisa Target | I4: Status | J4: Progress Bar
B5: 1 | C5: ='MASTER DATA'!C5 | D5: ='MASTER DATA'!D5 | E5: =IFERROR(IF('MASTER DATA'!C5="","",'MASTER DATA'!E5),"") | F5: =IFERROR(IF(C5="","",SUMIF('INPUT HARIAN'!D4:D503,C5,'INPUT HARIAN'!F4:F503)),"") | G5: =IFERROR(IF(E5=0,"",F5/E5),"") | H5: =IFERROR(IF(E5="","",E5-F5),"") | I5: =IFERROR(IF(G5="","",IF(G5>=1,"✅ TERCAPAI",IF(G5>=0.5,"⚠ MENUJU TARGET","❌ PERLU PERHATIAN"))),"—") | J5: =IFERROR(IF(G5="","",REPT("█",MIN(ROUND(G5*20,0),20))&" "&TEXT(G5,"0.0%")),"—")
B6: 2 | C6: ='MASTER DATA'!C6 | D6: ='MASTER DATA'!D6 | E6: =IFERROR(IF('MASTER DATA'!C6="","",'MASTER DATA'!E6),"") | F6: =IFERROR(IF(C6="","",SUMIF('INPUT HARIAN'!D4:D503,C6,'INPUT HARIAN'!F4:F503)),"") | G6: =IFERROR(IF(E6=0,"",F6/E6),"") | H6: =IFERROR(IF(E6="","",E6-F6),"") | I6: =IFERROR(IF(G6="","",IF(G6>=1,"✅ TERCAPAI",IF(G6>=0.5,"⚠ MENUJU TARGET","❌ PERLU PERHATIAN"))),"—") | J6: =IFERROR(IF(G6="","",REPT("█",MIN(ROUND(G6*20,0),20))&" "&TEXT(G6,"0.0%")),"—")
B7: 3 | C7: ='MASTER DATA'!C7 | D7: ='MASTER DATA'!D7 | E7: =IFERROR(IF('MASTER DATA'!C7="","",'MASTER DATA'!E7),"") | F7: =IFERROR(IF(C7="","",SUMIF('INPUT HARIAN'!D4:D503,C7,'INPUT HARIAN'!F4:F503)),"") | G7: =IFERROR(IF(E7=0,"",F7/E7),"") | H7: =IFERROR(IF(E7="","",E7-F7),"") | I7: =IFERROR(IF(G7="","",IF(G7>=1,"✅ TERCAPAI",IF(G7>=0.5,"⚠ MENUJU TARGET","❌ PERLU PERHATIAN"))),"—") | J7: =IFERROR(IF(G7="","",REPT("█",MIN(ROUND(G7*20,0),20))&" "&TEXT(G7,"0.0%")),"—")
B8: 4 | C8: ='MASTER DATA'!C8 | D8: ='MASTER DATA'!D8 | E8: =IFERROR(IF('MASTER DATA'!C8="","",'MASTER DATA'!E8),"") | F8: =IFERROR(IF(C8="","",SUMIF('INPUT HARIAN'!D4:D503,C8,'INPUT HARIAN'!F4:F503)),"") | G8: =IFERROR(IF(E8=0,"",F8/E8),"") | H8: =IFERROR(IF(E8="","",E8-F8),"") | I8: =IFERROR(IF(G8="","",IF(G8>=1,"✅ TERCAPAI",IF(G8>=0.5,"⚠ MENUJU TARGET","❌ PERLU PERHATIAN"))),"—") | J8: =IFERROR(IF(G8="","",REPT("█",MIN(ROUND(G8*20,0),20))&" "&TEXT(G8,"0.0%")),"—")
B9: 5 | C9: ='MASTER DATA'!C9 | D9: ='MASTER DATA'!D9 | E9: =IFERROR(IF('MASTER DATA'!C9="","",'MASTER DATA'!E9),"") | F9: =IFERROR(IF(C9="","",SUMIF('INPUT HARIAN'!D4:D503,C9,'INPUT HARIAN'!F4:F503)),"") | G9: =IFERROR(IF(E9=0,"",F9/E9),"") | H9: =IFERROR(IF(E9="","",E9-F9),"") | I9: =IFERROR(IF(G9="","",IF(G9>=1,"✅ TERCAPAI",IF(G9>=0.5,"⚠ MENUJU TARGET","❌ PERLU PERHATIAN"))),"—") | J9: =IFERROR(IF(G9="","",REPT("█",MIN(ROUND(G9*20,0),20))&" "&TEXT(G9,"0.0%")),"—")
B10: 6 | C10: ='MASTER DATA'!C10 | D10: ='MASTER DATA'!D10 | E10: =IFERROR(IF('MASTER DATA'!C10="","",'MASTER DATA'!E10),"") | F10: =IFERROR(IF(C10="","",SUMIF('INPUT HARIAN'!D4:D503,C10,'INPUT HARIAN'!F4:F503)),"") | G10: =IFERROR(IF(E10=0,"",F10/E10),"") | H10: =IFERROR(IF(E10="","",E10-F10),"") | I10: =IFERROR(IF(G10="","",IF(G10>=1,"✅ TERCAPAI",IF(G10>=0.5,"⚠ MENUJU TARGET","❌ PERLU PERHATIAN"))),"—") | J10: =IFERROR(IF(G10="","",REPT("█",MIN(ROUND(G10*20,0),20))&" "&TEXT(G10,"0.0%")),"—")
B11: 7 | C11: ='MASTER DATA'!C11 | D11: ='MASTER DATA'!D11 | E11: =IFERROR(IF('MASTER DATA'!C11="","",'MASTER DATA'!E11),"") | F11: =IFERROR(IF(C11="","",SUMIF('INPUT HARIAN'!D4:D503,C11,'INPUT HARIAN'!F4:F503)),"") | G11: =IFERROR(IF(E11=0,"",F11/E11),"") | H11: =IFERROR(IF(E11="","",E11-F11),"") | I11: =IFERROR(IF(G11="","",IF(G11>=1,"✅ TERCAPAI",IF(G11>=0.5,"⚠ MENUJU TARGET","❌ PERLU PERHATIAN"))),"—") | J11: =IFERROR(IF(G11="","",REPT("█",MIN(ROUND(G11*20,0),20))&" "&TEXT(G11,"0.0%")),"—")
B12: 8 | C12: ='MASTER DATA'!C12 | D12: ='MASTER DATA'!D12 | E12: =IFERROR(IF('MASTER DATA'!C12="","",'MASTER DATA'!E12),"") | F12: =IFERROR(IF(C12="","",SUMIF('INPUT HARIAN'!D4:D503,C12,'INPUT HARIAN'!F4:F503)),"") | G12: =IFERROR(IF(E12=0,"",F12/E12),"") | H12: =IFERROR(IF(E12="","",E12-F12),"") | I12: =IFERROR(IF(G12="","",IF(G12>=1,"✅ TERCAPAI",IF(G12>=0.5,"⚠ MENUJU TARGET","❌ PERLU PERHATIAN"))),"—") | J12: =IFERROR(IF(G12="","",REPT("█",MIN(ROUND(G12*20,0),20))&" "&TEXT(G12,"0.0%")),"—")
B13: 9 | C13: ='MASTER DATA'!C13 | D13: ='MASTER DATA'!D13 | E13: =IFERROR(IF('MASTER DATA'!C13="","",'MASTER DATA'!E13),"") | F13: =IFERROR(IF(C13="","",SUMIF('INPUT HARIAN'!D4:D503,C13,'INPUT HARIAN'!F4:F503)),"") | G13: =IFERROR(IF(E13=0,"",F13/E13),"") | H13: =IFERROR(IF(E13="","",E13-F13),"") | I13: =IFERROR(IF(G13="","",IF(G13>=1,"✅ TERCAPAI",IF(G13>=0.5,"⚠ MENUJU TARGET","❌ PERLU PERHATIAN"))),"—") | J13: =IFERROR(IF(G13="","",REPT("█",MIN(ROUND(G13*20,0),20))&" "&TEXT(G13,"0.0%")),"—")
B14: 10 | C14: ='MASTER DATA'!C14 | D14: ='MASTER DATA'!D14 | E14: =IFERROR(IF('MASTER DATA'!C14="","",'MASTER DATA'!E14),"") | F14: =IFERROR(IF(C14="","",SUMIF('INPUT HARIAN'!D4:D503,C14,'INPUT HARIAN'!F4:F503)),"") | G14: =IFERROR(IF(E14=0,"",F14/E14),"") | H14: =IFERROR(IF(E14="","",E14-F14),"") | I14: =IFERROR(IF(G14="","",IF(G14>=1,"✅ TERCAPAI",IF(G14>=0.5,"⚠ MENUJU TARGET","❌ PERLU PERHATIAN"))),"—") | J14: =IFERROR(IF(G14="","",REPT("█",MIN(ROUND(G14*20,0),20))&" "&TEXT(G14,"0.0%")),"—")
B15: 11 | C15: ='MASTER DATA'!C15 | D15: ='MASTER DATA'!D15 | E15: =IFERROR(IF('MASTER DATA'!C15="","",'MASTER DATA'!E15),"") | F15: =IFERROR(IF(C15="","",SUMIF('INPUT HARIAN'!D4:D503,C15,'INPUT HARIAN'!F4:F503)),"") | G15: =IFERROR(IF(E15=0,"",F15/E15),"") | H15: =IFERROR(IF(E15="","",E15-F15),"") | I15: =IFERROR(IF(G15="","",IF(G15>=1,"✅ TERCAPAI",IF(G15>=0.5,"⚠ MENUJU TARGET","❌ PERLU PERHATIAN"))),"—") | J15: =IFERROR(IF(G15="","",REPT("█",MIN(ROUND(G15*20,0),20))&" "&TEXT(G15,"0.0%")),"—")
B16: 12 | C16: ='MASTER DATA'!C16 | D16: ='MASTER DATA'!D16 | E16: =IFERROR(IF('MASTER DATA'!C16="","",'MASTER DATA'!E16),"") | F16: =IFERROR(IF(C16="","",SUMIF('INPUT HARIAN'!D4:D503,C16,'INPUT HARIAN'!F4:F503)),"") | G16: =IFERROR(IF(E16=0,"",F16/E16),"") | H16: =IFERROR(IF(E16="","",E16-F16),"") | I16: =IFERROR(IF(G16="","",IF(G16>=1,"✅ TERCAPAI",IF(G16>=0.5,"⚠ MENUJU TARGET","❌ PERLU PERHATIAN"))),"—") | J16: =IFERROR(IF(G16="","",REPT("█",MIN(ROUND(G16*20,0),20))&" "&TEXT(G16,"0.0%")),"—")
B17: 13 | C17: ='MASTER DATA'!C17 | D17: ='MASTER DATA'!D17 | E17: =IFERROR(IF('MASTER DATA'!C17="","",'MASTER DATA'!E17),"") | F17: =IFERROR(IF(C17="","",SUMIF('INPUT HARIAN'!D4:D503,C17,'INPUT HARIAN'!F4:F503)),"") | G17: =IFERROR(IF(E17=0,"",F17/E17),"") | H17: =IFERROR(IF(E17="","",E17-F17),"") | I17: =IFERROR(IF(G17="","",IF(G17>=1,"✅ TERCAPAI",IF(G17>=0.5,"⚠ MENUJU TARGET","❌ PERLU PERHATIAN"))),"—") | J17: =IFERROR(IF(G17="","",REPT("█",MIN(ROUND(G17*20,0),20))&" "&TEXT(G17,"0.0%")),"—")
B18: 14 | C18: ='MASTER DATA'!C18 | D18: ='MASTER DATA'!D18 | E18: =IFERROR(IF('MASTER DATA'!C18="","",'MASTER DATA'!E18),"") | F18: =IFERROR(IF(C18="","",SUMIF('INPUT HARIAN'!D4:D503,C18,'INPUT HARIAN'!F4:F503)),"") | G18: =IFERROR(IF(E18=0,"",F18/E18),"") | H18: =IFERROR(IF(E18="","",E18-F18),"") | I18: =IFERROR(IF(G18="","",IF(G18>=1,"✅ TERCAPAI",IF(G18>=0.5,"⚠ MENUJU TARGET","❌ PERLU PERHATIAN"))),"—") | J18: =IFERROR(IF(G18="","",REPT("█",MIN(ROUND(G18*20,0),20))&" "&TEXT(G18,"0.0%")),"—")
B19: 15 | C19: ='MASTER DATA'!C19 | D19: ='MASTER DATA'!D19 | E19: =IFERROR(IF('MASTER DATA'!C19="","",'MASTER DATA'!E19),"") | F19: =IFERROR(IF(C19="","",SUMIF('INPUT HARIAN'!D4:D503,C19,'INPUT HARIAN'!F4:F503)),"") | G19: =IFERROR(IF(E19=0,"",F19/E19),"") | H19: =IFERROR(IF(E19="","",E19-F19),"") | I19: =IFERROR(IF(G19="","",IF(G19>=1,"✅ TERCAPAI",IF(G19>=0.5,"⚠ MENUJU TARGET","❌ PERLU PERHATIAN"))),"—") | J19: =IFERROR(IF(G19="","",REPT("█",MIN(ROUND(G19*20,0),20))&" "&TEXT(G19,"0.0%")),"—")
B20: TOTAL KESELURUHAN | E20: =SUM(E5:E19) | F20: =SUM(F5:F19) | G20: =IFERROR(F20/E20,"") | H20: =E20-F20
B22: 👥 PENCAPAIAN DALAM SATUAN USER / PESERTA
B23: No | C23: Program | D23: PIC | E23: Target Bulanan | F23: Pencapaian | G23: % Capaian | H23: Sisa Target | I23: Status | J23: Progress Bar
B24: 1 | C24: ='MASTER DATA'!C5 | D24: ='MASTER DATA'!D5 | E24: =IFERROR(IF('MASTER DATA'!C5="","",'MASTER DATA'!F5),"") | F24: =IFERROR(IF(C24="","",SUMIF('INPUT HARIAN'!D4:D503,C24,'INPUT HARIAN'!G4:G503)),"") | G24: =IFERROR(IF(E24=0,"",F24/E24),"") | H24: =IFERROR(IF(E24="","",E24-F24),"") | I24: =IFERROR(IF(G24="","",IF(G24>=1,"✅ TERCAPAI",IF(G24>=0.5,"⚠ MENUJU TARGET","❌ PERLU PERHATIAN"))),"—") | J24: =IFERROR(IF(G24="","",REPT("█",MIN(ROUND(G24*20,0),20))&" "&TEXT(G24,"0.0%")),"—")
B25: 2 | C25: ='MASTER DATA'!C6 | D25: ='MASTER DATA'!D6 | E25: =IFERROR(IF('MASTER DATA'!C6="","",'MASTER DATA'!F6),"") | F25: =IFERROR(IF(C25="","",SUMIF('INPUT HARIAN'!D4:D503,C25,'INPUT HARIAN'!G4:G503)),"") | G25: =IFERROR(IF(E25=0,"",F25/E25),"") | H25: =IFERROR(IF(E25="","",E25-F25),"") | I25: =IFERROR(IF(G25="","",IF(G25>=1,"✅ TERCAPAI",IF(G25>=0.5,"⚠ MENUJU TARGET","❌ PERLU PERHATIAN"))),"—") | J25: =IFERROR(IF(G25="","",REPT("█",MIN(ROUND(G25*20,0),20))&" "&TEXT(G25,"0.0%")),"—")
B26: 3 | C26: ='MASTER DATA'!C7 | D26: ='MASTER DATA'!D7 | E26: =IFERROR(IF('MASTER DATA'!C7="","",'MASTER DATA'!F7),"") | F26: =IFERROR(IF(C26="","",SUMIF('INPUT HARIAN'!D4:D503,C26,'INPUT HARIAN'!G4:G503)),"") | G26: =IFERROR(IF(E26=0,"",F26/E26),"") | H26: =IFERROR(IF(E26="","",E26-F26),"") | I26: =IFERROR(IF(G26="","",IF(G26>=1,"✅ TERCAPAI",IF(G26>=0.5,"⚠ MENUJU TARGET","❌ PERLU PERHATIAN"))),"—") | J26: =IFERROR(IF(G26="","",REPT("█",MIN(ROUND(G26*20,0),20))&" "&TEXT(G26,"0.0%")),"—")
B27: 4 | C27: ='MASTER DATA'!C8 | D27: ='MASTER DATA'!D8 | E27: =IFERROR(IF('MASTER DATA'!C8="","",'MASTER DATA'!F8),"") | F27: =IFERROR(IF(C27="","",SUMIF('INPUT HARIAN'!D4:D503,C27,'INPUT HARIAN'!G4:G503)),"") | G27: =IFERROR(IF(E27=0,"",F27/E27),"") | H27: =IFERROR(IF(E27="","",E27-F27),"") | I27: =IFERROR(IF(G27="","",IF(G27>=1,"✅ TERCAPAI",IF(G27>=0.5,"⚠ MENUJU TARGET","❌ PERLU PERHATIAN"))),"—") | J27: =IFERROR(IF(G27="","",REPT("█",MIN(ROUND(G27*20,0),20))&" "&TEXT(G27,"0.0%")),"—")
B28: 5 | C28: ='MASTER DATA'!C9 | D28: ='MASTER DATA'!D9 | E28: =IFERROR(IF('MASTER DATA'!C9="","",'MASTER DATA'!F9),"") | F28: =IFERROR(IF(C28="","",SUMIF('INPUT HARIAN'!D4:D503,C28,'INPUT HARIAN'!G4:G503)),"") | G28: =IFERROR(IF(E28=0,"",F28/E28),"") | H28: =IFERROR(IF(E28="","",E28-F28),"") | I28: =IFERROR(IF(G28="","",IF(G28>=1,"✅ TERCAPAI",IF(G28>=0.5,"⚠ MENUJU TARGET","❌ PERLU PERHATIAN"))),"—") | J28: =IFERROR(IF(G28="","",REPT("█",MIN(ROUND(G28*20,0),20))&" "&TEXT(G28,"0.0%")),"—")
B29: 6 | C29: ='MASTER DATA'!C10 | D29: ='MASTER DATA'!D10 | E29: =IFERROR(IF('MASTER DATA'!C10="","",'MASTER DATA'!F10),"") | F29: =IFERROR(IF(C29="","",SUMIF('INPUT HARIAN'!D4:D503,C29,'INPUT HARIAN'!G4:G503)),"") | G29: =IFERROR(IF(E29=0,"",F29/E29),"") | H29: =IFERROR(IF(E29="","",E29-F29),"") | I29: =IFERROR(IF(G29="","",IF(G29>=1,"✅ TERCAPAI",IF(G29>=0.5,"⚠ MENUJU TARGET","❌ PERLU PERHATIAN"))),"—") | J29: =IFERROR(IF(G29="","",REPT("█",MIN(ROUND(G29*20,0),20))&" "&TEXT(G29,"0.0%")),"—")
B30: 7 | C30: ='MASTER DATA'!C11 | D30: ='MASTER DATA'!D11 | E30: =IFERROR(IF('MASTER DATA'!C11="","",'MASTER DATA'!F11),"") | F30: =IFERROR(IF(C30="","",SUMIF('INPUT HARIAN'!D4:D503,C30,'INPUT HARIAN'!G4:G503)),"") | G30: =IFERROR(IF(E30=0,"",F30/E30),"") | H30: =IFERROR(IF(E30="","",E30-F30),"") | I30: =IFERROR(IF(G30="","",IF(G30>=1,"✅ TERCAPAI",IF(G30>=0.5,"⚠ MENUJU TARGET","❌ PERLU PERHATIAN"))),"—") | J30: =IFERROR(IF(G30="","",REPT("█",MIN(ROUND(G30*20,0),20))&" "&TEXT(G30,"0.0%")),"—")
B31: 8 | C31: ='MASTER DATA'!C12 | D31: ='MASTER DATA'!D12 | E31: =IFERROR(IF('MASTER DATA'!C12="","",'MASTER DATA'!F12),"") | F31: =IFERROR(IF(C31="","",SUMIF('INPUT HARIAN'!D4:D503,C31,'INPUT HARIAN'!G4:G503)),"") | G31: =IFERROR(IF(E31=0,"",F31/E31),"") | H31: =IFERROR(IF(E31="","",E31-F31),"") | I31: =IFERROR(IF(G31="","",IF(G31>=1,"✅ TERCAPAI",IF(G31>=0.5,"⚠ MENUJU TARGET","❌ PERLU PERHATIAN"))),"—") | J31: =IFERROR(IF(G31="","",REPT("█",MIN(ROUND(G31*20,0),20))&" "&TEXT(G31,"0.0%")),"—")
B32: 9 | C32: ='MASTER DATA'!C13 | D32: ='MASTER DATA'!D13 | E32: =IFERROR(IF('MASTER DATA'!C13="","",'MASTER DATA'!F13),"") | F32: =IFERROR(IF(C32="","",SUMIF('INPUT HARIAN'!D4:D503,C32,'INPUT HARIAN'!G4:G503)),"") | G32: =IFERROR(IF(E32=0,"",F32/E32),"") | H32: =IFERROR(IF(E32="","",E32-F32),"") | I32: =IFERROR(IF(G32="","",IF(G32>=1,"✅ TERCAPAI",IF(G32>=0.5,"⚠ MENUJU TARGET","❌ PERLU PERHATIAN"))),"—") | J32: =IFERROR(IF(G32="","",REPT("█",MIN(ROUND(G32*20,0),20))&" "&TEXT(G32,"0.0%")),"—")
B33: 10 | C33: ='MASTER DATA'!C14 | D33: ='MASTER DATA'!D14 | E33: =IFERROR(IF('MASTER DATA'!C14="","",'MASTER DATA'!F14),"") | F33: =IFERROR(IF(C33="","",SUMIF('INPUT HARIAN'!D4:D503,C33,'INPUT HARIAN'!G4:G503)),"") | G33: =IFERROR(IF(E33=0,"",F33/E33),"") | H33: =IFERROR(IF(E33="","",E33-F33),"") | I33: =IFERROR(IF(G33="","",IF(G33>=1,"✅ TERCAPAI",IF(G33>=0.5,"⚠ MENUJU TARGET","❌ PERLU PERHATIAN"))),"—") | J33: =IFERROR(IF(G33="","",REPT("█",MIN(ROUND(G33*20,0),20))&" "&TEXT(G33,"0.0%")),"—")
B34: 11 | C34: ='MASTER DATA'!C15 | D34: ='MASTER DATA'!D15 | E34: =IFERROR(IF('MASTER DATA'!C15="","",'MASTER DATA'!F15),"") | F34: =IFERROR(IF(C34="","",SUMIF('INPUT HARIAN'!D4:D503,C34,'INPUT HARIAN'!G4:G503)),"") | G34: =IFERROR(IF(E34=0,"",F34/E34),"") | H34: =IFERROR(IF(E34="","",E34-F34),"") | I34: =IFERROR(IF(G34="","",IF(G34>=1,"✅ TERCAPAI",IF(G34>=0.5,"⚠ MENUJU TARGET","❌ PERLU PERHATIAN"))),"—") | J34: =IFERROR(IF(G34="","",REPT("█",MIN(ROUND(G34*20,0),20))&" "&TEXT(G34,"0.0%")),"—")
B35: 12 | C35: ='MASTER DATA'!C16 | D35: ='MASTER DATA'!D16 | E35: =IFERROR(IF('MASTER DATA'!C16="","",'MASTER DATA'!F16),"") | F35: =IFERROR(IF(C35="","",SUMIF('INPUT HARIAN'!D4:D503,C35,'INPUT HARIAN'!G4:G503)),"") | G35: =IFERROR(IF(E35=0,"",F35/E35),"") | H35: =IFERROR(IF(E35="","",E35-F35),"") | I35: =IFERROR(IF(G35="","",IF(G35>=1,"✅ TERCAPAI",IF(G35>=0.5,"⚠ MENUJU TARGET","❌ PERLU PERHATIAN"))),"—") | J35: =IFERROR(IF(G35="","",REPT("█",MIN(ROUND(G35*20,0),20))&" "&TEXT(G35,"0.0%")),"—")
B36: 13 | C36: ='MASTER DATA'!C17 | D36: ='MASTER DATA'!D17 | E36: =IFERROR(IF('MASTER DATA'!C17="","",'MASTER DATA'!F17),"") | F36: =IFERROR(IF(C36="","",SUMIF('INPUT HARIAN'!D4:D503,C36,'INPUT HARIAN'!G4:G503)),"") | G36: =IFERROR(IF(E36=0,"",F36/E36),"") | H36: =IFERROR(IF(E36="","",E36-F36),"") | I36: =IFERROR(IF(G36="","",IF(G36>=1,"✅ TERCAPAI",IF(G36>=0.5,"⚠ MENUJU TARGET","❌ PERLU PERHATIAN"))),"—") | J36: =IFERROR(IF(G36="","",REPT("█",MIN(ROUND(G36*20,0),20))&" "&TEXT(G36,"0.0%")),"—")
B37: 14 | C37: ='MASTER DATA'!C18 | D37: ='MASTER DATA'!D18 | E37: =IFERROR(IF('MASTER DATA'!C18="","",'MASTER DATA'!F18),"") | F37: =IFERROR(IF(C37="","",SUMIF('INPUT HARIAN'!D4:D503,C37,'INPUT HARIAN'!G4:G503)),"") | G37: =IFERROR(IF(E37=0,"",F37/E37),"") | H37: =IFERROR(IF(E37="","",E37-F37),"") | I37: =IFERROR(IF(G37="","",IF(G37>=1,"✅ TERCAPAI",IF(G37>=0.5,"⚠ MENUJU TARGET","❌ PERLU PERHATIAN"))),"—") | J37: =IFERROR(IF(G37="","",REPT("█",MIN(ROUND(G37*20,0),20))&" "&TEXT(G37,"0.0%")),"—")
B38: 15 | C38: ='MASTER DATA'!C19 | D38: ='MASTER DATA'!D19 | E38: =IFERROR(IF('MASTER DATA'!C19="","",'MASTER DATA'!F19),"") | F38: =IFERROR(IF(C38="","",SUMIF('INPUT HARIAN'!D4:D503,C38,'INPUT HARIAN'!G4:G503)),"") | G38: =IFERROR(IF(E38=0,"",F38/E38),"") | H38: =IFERROR(IF(E38="","",E38-F38),"") | I38: =IFERROR(IF(G38="","",IF(G38>=1,"✅ TERCAPAI",IF(G38>=0.5,"⚠ MENUJU TARGET","❌ PERLU PERHATIAN"))),"—") | J38: =IFERROR(IF(G38="","",REPT("█",MIN(ROUND(G38*20,0),20))&" "&TEXT(G38,"0.0%")),"—")
B39: TOTAL KESELURUHAN | E39: =SUM(E24:E38) | F39: =SUM(F24:F38) | G39: =IFERROR(F39/E39,"") | H39: =E39-F39

Sheet DASHBOARD HARIAN
B1: ="DASHBOARD HARIAN — "&'MASTER DATA'!H2
B2: Tanggal dan hari dihitung otomatis sesuai periode. Baris hari yang tidak ada di bulan aktif otomatis dikosongkan.
B3: 📊 REKAP HARIAN — RUPIAH (Rp)
B4: No | C4: Tanggal | D4: Hari | E4: Target Harian | F4: Pencapaian Harian | G4: % Harian | H4: Status | I4: Kumulatif Target | J4: Kumulatif Capaian | K4: % Kumulatif | L4: Gap Kumulatif
B5: 1 | C5: =IFERROR(IF(1>'MASTER DATA'!I2,"",DATE('MASTER DATA'!F2,'MASTER DATA'!D2,1)),"") | D5: =IF(C5="","",TEXT(C5,"DDDD")) | E5: =IF(C5="","",IFERROR(SUM('MASTER DATA'!J5:J19),0)) | F5: =IF(C5="","",IFERROR(SUMIF('INPUT HARIAN'!C4:C503,C5,'INPUT HARIAN'!F4:F503),0)) | G5: =IFERROR(IF(C5="","",IF(E5=0,"",F5/E5)),"") | H5: =IF(C5="","",IF(F5=0,"—",IF(G5>=1,"✅ TERCAPAI",IF(G5>=0.5,"⚠ MENUJU TARGET","❌ BELUM TERCAPAI")))) | I5: =IFERROR(IF(C5="","",SUM(E5)),"") | J5: =IFERROR(IF(C5="","",SUM(F5)),"") | K5: =IFERROR(IF(C5="","",IF(I5=0,"",J5/I5)),"") | L5: =IFERROR(IF(C5="","",I5-J5),"")
B6: 2 | C6: =IFERROR(IF(2>'MASTER DATA'!I2,"",DATE('MASTER DATA'!F2,'MASTER DATA'!D2,2)),"") | D6: =IF(C6="","",TEXT(C6,"DDDD")) | E6: =IF(C6="","",IFERROR(SUM('MASTER DATA'!J5:J19),0)) | F6: =IF(C6="","",IFERROR(SUMIF('INPUT HARIAN'!C4:C503,C6,'INPUT HARIAN'!F4:F503),0)) | G6: =IFERROR(IF(C6="","",IF(E6=0,"",F6/E6)),"") | H6: =IF(C6="","",IF(F6=0,"—",IF(G6>=1,"✅ TERCAPAI",IF(G6>=0.5,"⚠ MENUJU TARGET","❌ BELUM TERCAPAI")))) | I6: =IFERROR(IF(C6="","",SUM(E5:E6)),"") | J6: =IFERROR(IF(C6="","",SUM(F5:F6)),"") | K6: =IFERROR(IF(C6="","",IF(I6=0,"",J6/I6)),"") | L6: =IFERROR(IF(C6="","",I6-J6),"")
B7: 3 | C7: =IFERROR(IF(3>'MASTER DATA'!I2,"",DATE('MASTER DATA'!F2,'MASTER DATA'!D2,3)),"") | D7: =IF(C7="","",TEXT(C7,"DDDD")) | E7: =IF(C7="","",IFERROR(SUM('MASTER DATA'!J5:J19),0)) | F7: =IF(C7="","",IFERROR(SUMIF('INPUT HARIAN'!C4:C503,C7,'INPUT HARIAN'!F4:F503),0)) | G7: =IFERROR(IF(C7="","",IF(E7=0,"",F7/E7)),"") | H7: =IF(C7="","",IF(F7=0,"—",IF(G7>=1,"✅ TERCAPAI",IF(G7>=0.5,"⚠ MENUJU TARGET","❌ BELUM TERCAPAI")))) | I7: =IFERROR(IF(C7="","",SUM(E5:E7)),"") | J7: =IFERROR(IF(C7="","",SUM(F5:F7)),"") | K7: =IFERROR(IF(C7="","",IF(I7=0,"",J7/I7)),"") | L7: =IFERROR(IF(C7="","",I7-J7),"")
B8: 4 | C8: =IFERROR(IF(4>'MASTER DATA'!I2,"",DATE('MASTER DATA'!F2,'MASTER DATA'!D2,4)),"") | D8: =IF(C8="","",TEXT(C8,"DDDD")) | E8: =IF(C8="","",IFERROR(SUM('MASTER DATA'!J5:J19),0)) | F8: =IF(C8="","",IFERROR(SUMIF('INPUT HARIAN'!C4:C503,C8,'INPUT HARIAN'!F4:F503),0)) | G8: =IFERROR(IF(C8="","",IF(E8=0,"",F8/E8)),"") | H8: =IF(C8="","",IF(F8=0,"—",IF(G8>=1,"✅ TERCAPAI",IF(G8>=0.5,"⚠ MENUJU TARGET","❌ BELUM TERCAPAI")))) | I8: =IFERROR(IF(C8="","",SUM(E5:E8)),"") | J8: =IFERROR(IF(C8="","",SUM(F5:F8)),"") | K8: =IFERROR(IF(C8="","",IF(I8=0,"",J8/I8)),"") | L8: =IFERROR(IF(C8="","",I8-J8),"")
B9: 5 | C9: =IFERROR(IF(5>'MASTER DATA'!I2,"",DATE('MASTER DATA'!F2,'MASTER DATA'!D2,5)),"") | D9: =IF(C9="","",TEXT(C9,"DDDD")) | E9: =IF(C9="","",IFERROR(SUM('MASTER DATA'!J5:J19),0)) | F9: =IF(C9="","",IFERROR(SUMIF('INPUT HARIAN'!C4:C503,C9,'INPUT HARIAN'!F4:F503),0)) | G9: =IFERROR(IF(C9="","",IF(E9=0,"",F9/E9)),"") | H9: =IF(C9="","",IF(F9=0,"—",IF(G9>=1,"✅ TERCAPAI",IF(G9>=0.5,"⚠ MENUJU TARGET","❌ BELUM TERCAPAI")))) | I9: =IFERROR(IF(C9="","",SUM(E5:E9)),"") | J9: =IFERROR(IF(C9="","",SUM(F5:F9)),"") | K9: =IFERROR(IF(C9="","",IF(I9=0,"",J9/I9)),"") | L9: =IFERROR(IF(C9="","",I9-J9),"")
B10: 6 | C10: =IFERROR(IF(6>'MASTER DATA'!I2,"",DATE('MASTER DATA'!F2,'MASTER DATA'!D2,6)),"") | D10: =IF(C10="","",TEXT(C10,"DDDD")) | E10: =IF(C10="","",IFERROR(SUM('MASTER DATA'!J5:J19),0)) | F10: =IF(C10="","",IFERROR(SUMIF('INPUT HARIAN'!C4:C503,C10,'INPUT HARIAN'!F4:F503),0)) | G10: =IFERROR(IF(C10="","",IF(E10=0,"",F10/E10)),"") | H10: =IF(C10="","",IF(F10=0,"—",IF(G10>=1,"✅ TERCAPAI",IF(G10>=0.5,"⚠ MENUJU TARGET","❌ BELUM TERCAPAI")))) | I10: =IFERROR(IF(C10="","",SUM(E5:E10)),"") | J10: =IFERROR(IF(C10="","",SUM(F5:F10)),"") | K10: =IFERROR(IF(C10="","",IF(I10=0,"",J10/I10)),"") | L10: =IFERROR(IF(C10="","",I10-J10),"")
B11: 7 | C11: =IFERROR(IF(7>'MASTER DATA'!I2,"",DATE('MASTER DATA'!F2,'MASTER DATA'!D2,7)),"") | D11: =IF(C11="","",TEXT(C11,"DDDD")) | E11: =IF(C11="","",IFERROR(SUM('MASTER DATA'!J5:J19),0)) | F11: =IF(C11="","",IFERROR(SUMIF('INPUT HARIAN'!C4:C503,C11,'INPUT HARIAN'!F4:F503),0)) | G11: =IFERROR(IF(C11="","",IF(E11=0,"",F11/E11)),"") | H11: =IF(C11="","",IF(F11=0,"—",IF(G11>=1,"✅ TERCAPAI",IF(G11>=0.5,"⚠ MENUJU TARGET","❌ BELUM TERCAPAI")))) | I11: =IFERROR(IF(C11="","",SUM(E5:E11)),"") | J11: =IFERROR(IF(C11="","",SUM(F5:F11)),"") | K11: =IFERROR(IF(C11="","",IF(I11=0,"",J11/I11)),"") | L11: =IFERROR(IF(C11="","",I11-J11),"")
B12: 8 | C12: =IFERROR(IF(8>'MASTER DATA'!I2,"",DATE('MASTER DATA'!F2,'MASTER DATA'!D2,8)),"") | D12: =IF(C12="","",TEXT(C12,"DDDD")) | E12: =IF(C12="","",IFERROR(SUM('MASTER DATA'!J5:J19),0)) | F12: =IF(C12="","",IFERROR(SUMIF('INPUT HARIAN'!C4:C503,C12,'INPUT HARIAN'!F4:F503),0)) | G12: =IFERROR(IF(C12="","",IF(E12=0,"",F12/E12)),"") | H12: =IF(C12="","",IF(F12=0,"—",IF(G12>=1,"✅ TERCAPAI",IF(G12>=0.5,"⚠ MENUJU TARGET","❌ BELUM TERCAPAI")))) | I12: =IFERROR(IF(C12="","",SUM(E5:E12)),"") | J12: =IFERROR(IF(C12="","",SUM(F5:F12)),"") | K12: =IFERROR(IF(C12="","",IF(I12=0,"",J12/I12)),"") | L12: =IFERROR(IF(C12="","",I12-J12),"")
B13: 9 | C13: =IFERROR(IF(9>'MASTER DATA'!I2,"",DATE('MASTER DATA'!F2,'MASTER DATA'!D2,9)),"") | D13: =IF(C13="","",TEXT(C13,"DDDD")) | E13: =IF(C13="","",IFERROR(SUM('MASTER DATA'!J5:J19),0)) | F13: =IF(C13="","",IFERROR(SUMIF('INPUT HARIAN'!C4:C503,C13,'INPUT HARIAN'!F4:F503),0)) | G13: =IFERROR(IF(C13="","",IF(E13=0,"",F13/E13)),"") | H13: =IF(C13="","",IF(F13=0,"—",IF(G13>=1,"✅ TERCAPAI",IF(G13>=0.5,"⚠ MENUJU TARGET","❌ BELUM TERCAPAI")))) | I13: =IFERROR(IF(C13="","",SUM(E5:E13)),"") | J13: =IFERROR(IF(C13="","",SUM(F5:F13)),"") | K13: =IFERROR(IF(C13="","",IF(I13=0,"",J13/I13)),"") | L13: =IFERROR(IF(C13="","",I13-J13),"")
B14: 10 | C14: =IFERROR(IF(10>'MASTER DATA'!I2,"",DATE('MASTER DATA'!F2,'MASTER DATA'!D2,10)),"") | D14: =IF(C14="","",TEXT(C14,"DDDD")) | E14: =IF(C14="","",IFERROR(SUM('MASTER DATA'!J5:J19),0)) | F14: =IF(C14="","",IFERROR(SUMIF('INPUT HARIAN'!C4:C503,C14,'INPUT HARIAN'!F4:F503),0)) | G14: =IFERROR(IF(C14="","",IF(E14=0,"",F14/E14)),"") | H14: =IF(C14="","",IF(F14=0,"—",IF(G14>=1,"✅ TERCAPAI",IF(G14>=0.5,"⚠ MENUJU TARGET","❌ BELUM TERCAPAI")))) | I14: =IFERROR(IF(C14="","",SUM(E5:E14)),"") | J14: =IFERROR(IF(C14="","",SUM(F5:F14)),"") | K14: =IFERROR(IF(C14="","",IF(I14=0,"",J14/I14)),"") | L14: =IFERROR(IF(C14="","",I14-J14),"")
B15: 11 | C15: =IFERROR(IF(11>'MASTER DATA'!I2,"",DATE('MASTER DATA'!F2,'MASTER DATA'!D2,11)),"") | D15: =IF(C15="","",TEXT(C15,"DDDD")) | E15: =IF(C15="","",IFERROR(SUM('MASTER DATA'!J5:J19),0)) | F15: =IF(C15="","",IFERROR(SUMIF('INPUT HARIAN'!C4:C503,C15,'INPUT HARIAN'!F4:F503),0)) | G15: =IFERROR(IF(C15="","",IF(E15=0,"",F15/E15)),"") | H15: =IF(C15="","",IF(F15=0,"—",IF(G15>=1,"✅ TERCAPAI",IF(G15>=0.5,"⚠ MENUJU TARGET","❌ BELUM TERCAPAI")))) | I15: =IFERROR(IF(C15="","",SUM(E5:E15)),"") | J15: =IFERROR(IF(C15="","",SUM(F5:F15)),"") | K15: =IFERROR(IF(C15="","",IF(I15=0,"",J15/I15)),"") | L15: =IFERROR(IF(C15="","",I15-J15),"")
B16: 12 | C16: =IFERROR(IF(12>'MASTER DATA'!I2,"",DATE('MASTER DATA'!F2,'MASTER DATA'!D2,12)),"") | D16: =IF(C16="","",TEXT(C16,"DDDD")) | E16: =IF(C16="","",IFERROR(SUM('MASTER DATA'!J5:J19),0)) | F16: =IF(C16="","",IFERROR(SUMIF('INPUT HARIAN'!C4:C503,C16,'INPUT HARIAN'!F4:F503),0)) | G16: =IFERROR(IF(C16="","",IF(E16=0,"",F16/E16)),"") | H16: =IF(C16="","",IF(F16=0,"—",IF(G16>=1,"✅ TERCAPAI",IF(G16>=0.5,"⚠ MENUJU TARGET","❌ BELUM TERCAPAI")))) | I16: =IFERROR(IF(C16="","",SUM(E5:E16)),"") | J16: =IFERROR(IF(C16="","",SUM(F5:F16)),"") | K16: =IFERROR(IF(C16="","",IF(I16=0,"",J16/I16)),"") | L16: =IFERROR(IF(C16="","",I16-J16),"")
B17: 13 | C17: =IFERROR(IF(13>'MASTER DATA'!I2,"",DATE('MASTER DATA'!F2,'MASTER DATA'!D2,13)),"") | D17: =IF(C17="","",TEXT(C17,"DDDD")) | E17: =IF(C17="","",IFERROR(SUM('MASTER DATA'!J5:J19),0)) | F17: =IF(C17="","",IFERROR(SUMIF('INPUT HARIAN'!C4:C503,C17,'INPUT HARIAN'!F4:F503),0)) | G17: =IFERROR(IF(C17="","",IF(E17=0,"",F17/E17)),"") | H17: =IF(C17="","",IF(F17=0,"—",IF(G17>=1,"✅ TERCAPAI",IF(G17>=0.5,"⚠ MENUJU TARGET","❌ BELUM TERCAPAI")))) | I17: =IFERROR(IF(C17="","",SUM(E5:E17)),"") | J17: =IFERROR(IF(C17="","",SUM(F5:F17)),"") | K17: =IFERROR(IF(C17="","",IF(I17=0,"",J17/I17)),"") | L17: =IFERROR(IF(C17="","",I17-J17),"")
B18: 14 | C18: =IFERROR(IF(14>'MASTER DATA'!I2,"",DATE('MASTER DATA'!F2,'MASTER DATA'!D2,14)),"") | D18: =IF(C18="","",TEXT(C18,"DDDD")) | E18: =IF(C18="","",IFERROR(SUM('MASTER DATA'!J5:J19),0)) | F18: =IF(C18="","",IFERROR(SUMIF('INPUT HARIAN'!C4:C503,C18,'INPUT HARIAN'!F4:F503),0)) | G18: =IFERROR(IF(C18="","",IF(E18=0,"",F18/E18)),"") | H18: =IF(C18="","",IF(F18=0,"—",IF(G18>=1,"✅ TERCAPAI",IF(G18>=0.5,"⚠ MENUJU TARGET","❌ BELUM TERCAPAI")))) | I18: =IFERROR(IF(C18="","",SUM(E5:E18)),"") | J18: =IFERROR(IF(C18="","",SUM(F5:F18)),"") | K18: =IFERROR(IF(C18="","",IF(I18=0,"",J18/I18)),"") | L18: =IFERROR(IF(C18="","",I18-J18),"")
B19: 15 | C19: =IFERROR(IF(15>'MASTER DATA'!I2,"",DATE('MASTER DATA'!F2,'MASTER DATA'!D2,15)),"") | D19: =IF(C19="","",TEXT(C19,"DDDD")) | E19: =IF(C19="","",IFERROR(SUM('MASTER DATA'!J5:J19),0)) | F19: =IF(C19="","",IFERROR(SUMIF('INPUT HARIAN'!C4:C503,C19,'INPUT HARIAN'!F4:F503),0)) | G19: =IFERROR(IF(C19="","",IF(E19=0,"",F19/E19)),"") | H19: =IF(C19="","",IF(F19=0,"—",IF(G19>=1,"✅ TERCAPAI",IF(G19>=0.5,"⚠ MENUJU TARGET","❌ BELUM TERCAPAI")))) | I19: =IFERROR(IF(C19="","",SUM(E5:E19)),"") | J19: =IFERROR(IF(C19="","",SUM(F5:F19)),"") | K19: =IFERROR(IF(C19="","",IF(I19=0,"",J19/I19)),"") | L19: =IFERROR(IF(C19="","",I19-J19),"")
B20: 16 | C20: =IFERROR(IF(16>'MASTER DATA'!I2,"",DATE('MASTER DATA'!F2,'MASTER DATA'!D2,16)),"") | D20: =IF(C20="","",TEXT(C20,"DDDD")) | E20: =IF(C20="","",IFERROR(SUM('MASTER DATA'!J5:J19),0)) | F20: =IF(C20="","",IFERROR(SUMIF('INPUT HARIAN'!C4:C503,C20,'INPUT HARIAN'!F4:F503),0)) | G20: =IFERROR(IF(C20="","",IF(E20=0,"",F20/E20)),"") | H20: =IF(C20="","",IF(F20=0,"—",IF(G20>=1,"✅ TERCAPAI",IF(G20>=0.5,"⚠ MENUJU TARGET","❌ BELUM TERCAPAI")))) | I20: =IFERROR(IF(C20="","",SUM(E5:E20)),"") | J20: =IFERROR(IF(C20="","",SUM(F5:F20)),"") | K20: =IFERROR(IF(C20="","",IF(I20=0,"",J20/I20)),"") | L20: =IFERROR(IF(C20="","",I20-J20),"")
B21: 17 | C21: =IFERROR(IF(17>'MASTER DATA'!I2,"",DATE('MASTER DATA'!F2,'MASTER DATA'!D2,17)),"") | D21: =IF(C21="","",TEXT(C21,"DDDD")) | E21: =IF(C21="","",IFERROR(SUM('MASTER DATA'!J5:J19),0)) | F21: =IF(C21="","",IFERROR(SUMIF('INPUT HARIAN'!C4:C503,C21,'INPUT HARIAN'!F4:F503),0)) | G21: =IFERROR(IF(C21="","",IF(E21=0,"",F21/E21)),"") | H21: =IF(C21="","",IF(F21=0,"—",IF(G21>=1,"✅ TERCAPAI",IF(G21>=0.5,"⚠ MENUJU TARGET","❌ BELUM TERCAPAI")))) | I21: =IFERROR(IF(C21="","",SUM(E5:E21)),"") | J21: =IFERROR(IF(C21="","",SUM(F5:F21)),"") | K21: =IFERROR(IF(C21="","",IF(I21=0,"",J21/I21)),"") | L21: =IFERROR(IF(C21="","",I21-J21),"")
B22: 18 | C22: =IFERROR(IF(18>'MASTER DATA'!I2,"",DATE('MASTER DATA'!F2,'MASTER DATA'!D2,18)),"") | D22: =IF(C22="","",TEXT(C22,"DDDD")) | E22: =IF(C22="","",IFERROR(SUM('MASTER DATA'!J5:J19),0)) | F22: =IF(C22="","",IFERROR(SUMIF('INPUT HARIAN'!C4:C503,C22,'INPUT HARIAN'!F4:F503),0)) | G22: =IFERROR(IF(C22="","",IF(E22=0,"",F22/E22)),"") | H22: =IF(C22="","",IF(F22=0,"—",IF(G22>=1,"✅ TERCAPAI",IF(G22>=0.5,"⚠ MENUJU TARGET","❌ BELUM TERCAPAI")))) | I22: =IFERROR(IF(C22="","",SUM(E5:E22)),"") | J22: =IFERROR(IF(C22="","",SUM(F5:F22)),"") | K22: =IFERROR(IF(C22="","",IF(I22=0,"",J22/I22)),"") | L22: =IFERROR(IF(C22="","",I22-J22),"")
B23: 19 | C23: =IFERROR(IF(19>'MASTER DATA'!I2,"",DATE('MASTER DATA'!F2,'MASTER DATA'!D2,19)),"") | D23: =IF(C23="","",TEXT(C23,"DDDD")) | E23: =IF(C23="","",IFERROR(SUM('MASTER DATA'!J5:J19),0)) | F23: =IF(C23="","",IFERROR(SUMIF('INPUT HARIAN'!C4:C503,C23,'INPUT HARIAN'!F4:F503),0)) | G23: =IFERROR(IF(C23="","",IF(E23=0,"",F23/E23)),"") | H23: =IF(C23="","",IF(F23=0,"—",IF(G23>=1,"✅ TERCAPAI",IF(G23>=0.5,"⚠ MENUJU TARGET","❌ BELUM TERCAPAI")))) | I23: =IFERROR(IF(C23="","",SUM(E5:E23)),"") | J23: =IFERROR(IF(C23="","",SUM(F5:F23)),"") | K23: =IFERROR(IF(C23="","",IF(I23=0,"",J23/I23)),"") | L23: =IFERROR(IF(C23="","",I23-J23),"")
B24: 20 | C24: =IFERROR(IF(20>'MASTER DATA'!I2,"",DATE('MASTER DATA'!F2,'MASTER DATA'!D2,20)),"") | D24: =IF(C24="","",TEXT(C24,"DDDD")) | E24: =IF(C24="","",IFERROR(SUM('MASTER DATA'!J5:J19),0)) | F24: =IF(C24="","",IFERROR(SUMIF('INPUT HARIAN'!C4:C503,C24,'INPUT HARIAN'!F4:F503),0)) | G24: =IFERROR(IF(C24="","",IF(E24=0,"",F24/E24)),"") | H24: =IF(C24="","",IF(F24=0,"—",IF(G24>=1,"✅ TERCAPAI",IF(G24>=0.5,"⚠ MENUJU TARGET","❌ BELUM TERCAPAI")))) | I24: =IFERROR(IF(C24="","",SUM(E5:E24)),"") | J24: =IFERROR(IF(C24="","",SUM(F5:F24)),"") | K24: =IFERROR(IF(C24="","",IF(I24=0,"",J24/I24)),"") | L24: =IFERROR(IF(C24="","",I24-J24),"")
B25: 21 | C25: =IFERROR(IF(21>'MASTER DATA'!I2,"",DATE('MASTER DATA'!F2,'MASTER DATA'!D2,21)),"") | D25: =IF(C25="","",TEXT(C25,"DDDD")) | E25: =IF(C25="","",IFERROR(SUM('MASTER DATA'!J5:J19),0)) | F25: =IF(C25="","",IFERROR(SUMIF('INPUT HARIAN'!C4:C503,C25,'INPUT HARIAN'!F4:F503),0)) | G25: =IFERROR(IF(C25="","",IF(E25=0,"",F25/E25)),"") | H25: =IF(C25="","",IF(F25=0,"—",IF(G25>=1,"✅ TERCAPAI",IF(G25>=0.5,"⚠ MENUJU TARGET","❌ BELUM TERCAPAI")))) | I25: =IFERROR(IF(C25="","",SUM(E5:E25)),"") | J25: =IFERROR(IF(C25="","",SUM(F5:F25)),"") | K25: =IFERROR(IF(C25="","",IF(I25=0,"",J25/I25)),"") | L25: =IFERROR(IF(C25="","",I25-J25),"")
B26: 22 | C26: =IFERROR(IF(22>'MASTER DATA'!I2,"",DATE('MASTER DATA'!F2,'MASTER DATA'!D2,22)),"") | D26: =IF(C26="","",TEXT(C26,"DDDD")) | E26: =IF(C26="","",IFERROR(SUM('MASTER DATA'!J5:J19),0)) | F26: =IF(C26="","",IFERROR(SUMIF('INPUT HARIAN'!C4:C503,C26,'INPUT HARIAN'!F4:F503),0)) | G26: =IFERROR(IF(C26="","",IF(E26=0,"",F26/E26)),"") | H26: =IF(C26="","",IF(F26=0,"—",IF(G26>=1,"✅ TERCAPAI",IF(G26>=0.5,"⚠ MENUJU TARGET","❌ BELUM TERCAPAI")))) | I26: =IFERROR(IF(C26="","",SUM(E5:E26)),"") | J26: =IFERROR(IF(C26="","",SUM(F5:F26)),"") | K26: =IFERROR(IF(C26="","",IF(I26=0,"",J26/I26)),"") | L26: =IFERROR(IF(C26="","",I26-J26),"")
B27: 23 | C27: =IFERROR(IF(23>'MASTER DATA'!I2,"",DATE('MASTER DATA'!F2,'MASTER DATA'!D2,23)),"") | D27: =IF(C27="","",TEXT(C27,"DDDD")) | E27: =IF(C27="","",IFERROR(SUM('MASTER DATA'!J5:J19),0)) | F27: =IF(C27="","",IFERROR(SUMIF('INPUT HARIAN'!C4:C503,C27,'INPUT HARIAN'!F4:F503),0)) | G27: =IFERROR(IF(C27="","",IF(E27=0,"",F27/E27)),"") | H27: =IF(C27="","",IF(F27=0,"—",IF(G27>=1,"✅ TERCAPAI",IF(G27>=0.5,"⚠ MENUJU TARGET","❌ BELUM TERCAPAI")))) | I27: =IFERROR(IF(C27="","",SUM(E5:E27)),"") | J27: =IFERROR(IF(C27="","",SUM(F5:F27)),"") | K27: =IFERROR(IF(C27="","",IF(I27=0,"",J27/I27)),"") | L27: =IFERROR(IF(C27="","",I27-J27),"")
B28: 24 | C28: =IFERROR(IF(24>'MASTER DATA'!I2,"",DATE('MASTER DATA'!F2,'MASTER DATA'!D2,24)),"") | D28: =IF(C28="","",TEXT(C28,"DDDD")) | E28: =IF(C28="","",IFERROR(SUM('MASTER DATA'!J5:J19),0)) | F28: =IF(C28="","",IFERROR(SUMIF('INPUT HARIAN'!C4:C503,C28,'INPUT HARIAN'!F4:F503),0)) | G28: =IFERROR(IF(C28="","",IF(E28=0,"",F28/E28)),"") | H28: =IF(C28="","",IF(F28=0,"—",IF(G28>=1,"✅ TERCAPAI",IF(G28>=0.5,"⚠ MENUJU TARGET","❌ BELUM TERCAPAI")))) | I28: =IFERROR(IF(C28="","",SUM(E5:E28)),"") | J28: =IFERROR(IF(C28="","",SUM(F5:F28)),"") | K28: =IFERROR(IF(C28="","",IF(I28=0,"",J28/I28)),"") | L28: =IFERROR(IF(C28="","",I28-J28),"")
B29: 25 | C29: =IFERROR(IF(25>'MASTER DATA'!I2,"",DATE('MASTER DATA'!F2,'MASTER DATA'!D2,25)),"") | D29: =IF(C29="","",TEXT(C29,"DDDD")) | E29: =IF(C29="","",IFERROR(SUM('MASTER DATA'!J5:J19),0)) | F29: =IF(C29="","",IFERROR(SUMIF('INPUT HARIAN'!C4:C503,C29,'INPUT HARIAN'!F4:F503),0)) | G29: =IFERROR(IF(C29="","",IF(E29=0,"",F29/E29)),"") | H29: =IF(C29="","",IF(F29=0,"—",IF(G29>=1,"✅ TERCAPAI",IF(G29>=0.5,"⚠ MENUJU TARGET","❌ BELUM TERCAPAI")))) | I29: =IFERROR(IF(C29="","",SUM(E5:E29)),"") | J29: =IFERROR(IF(C29="","",SUM(F5:F29)),"") | K29: =IFERROR(IF(C29="","",IF(I29=0,"",J29/I29)),"") | L29: =IFERROR(IF(C29="","",I29-J29),"")
B30: 26 | C30: =IFERROR(IF(26>'MASTER DATA'!I2,"",DATE('MASTER DATA'!F2,'MASTER DATA'!D2,26)),"") | D30: =IF(C30="","",TEXT(C30,"DDDD")) | E30: =IF(C30="","",IFERROR(SUM('MASTER DATA'!J5:J19),0)) | F30: =IF(C30="","",IFERROR(SUMIF('INPUT HARIAN'!C4:C503,C30,'INPUT HARIAN'!F4:F503),0)) | G30: =IFERROR(IF(C30="","",IF(E30=0,"",F30/E30)),"") | H30: =IF(C30="","",IF(F30=0,"—",IF(G30>=1,"✅ TERCAPAI",IF(G30>=0.5,"⚠ MENUJU TARGET","❌ BELUM TERCAPAI")))) | I30: =IFERROR(IF(C30="","",SUM(E5:E30)),"") | J30: =IFERROR(IF(C30="","",SUM(F5:F30)),"") | K30: =IFERROR(IF(C30="","",IF(I30=0,"",J30/I30)),"") | L30: =IFERROR(IF(C30="","",I30-J30),"")
B31: 27 | C31: =IFERROR(IF(27>'MASTER DATA'!I2,"",DATE('MASTER DATA'!F2,'MASTER DATA'!D2,27)),"") | D31: =IF(C31="","",TEXT(C31,"DDDD")) | E31: =IF(C31="","",IFERROR(SUM('MASTER DATA'!J5:J19),0)) | F31: =IF(C31="","",IFERROR(SUMIF('INPUT HARIAN'!C4:C503,C31,'INPUT HARIAN'!F4:F503),0)) | G31: =IFERROR(IF(C31="","",IF(E31=0,"",F31/E31)),"") | H31: =IF(C31="","",IF(F31=0,"—",IF(G31>=1,"✅ TERCAPAI",IF(G31>=0.5,"⚠ MENUJU TARGET","❌ BELUM TERCAPAI")))) | I31: =IFERROR(IF(C31="","",SUM(E5:E31)),"") | J31: =IFERROR(IF(C31="","",SUM(F5:F31)),"") | K31: =IFERROR(IF(C31="","",IF(I31=0,"",J31/I31)),"") | L31: =IFERROR(IF(C31="","",I31-J31),"")
B32: 28 | C32: =IFERROR(IF(28>'MASTER DATA'!I2,"",DATE('MASTER DATA'!F2,'MASTER DATA'!D2,28)),"") | D32: =IF(C32="","",TEXT(C32,"DDDD")) | E32: =IF(C32="","",IFERROR(SUM('MASTER DATA'!J5:J19),0)) | F32: =IF(C32="","",IFERROR(SUMIF('INPUT HARIAN'!C4:C503,C32,'INPUT HARIAN'!F4:F503),0)) | G32: =IFERROR(IF(C32="","",IF(E32=0,"",F32/E32)),"") | H32: =IF(C32="","",IF(F32=0,"—",IF(G32>=1,"✅ TERCAPAI",IF(G32>=0.5,"⚠ MENUJU TARGET","❌ BELUM TERCAPAI")))) | I32: =IFERROR(IF(C32="","",SUM(E5:E32)),"") | J32: =IFERROR(IF(C32="","",SUM(F5:F32)),"") | K32: =IFERROR(IF(C32="","",IF(I32=0,"",J32/I32)),"") | L32: =IFERROR(IF(C32="","",I32-J32),"")
B33: 29 | C33: =IFERROR(IF(29>'MASTER DATA'!I2,"",DATE('MASTER DATA'!F2,'MASTER DATA'!D2,29)),"") | D33: =IF(C33="","",TEXT(C33,"DDDD")) | E33: =IF(C33="","",IFERROR(SUM('MASTER DATA'!J5:J19),0)) | F33: =IF(C33="","",IFERROR(SUMIF('INPUT HARIAN'!C4:C503,C33,'INPUT HARIAN'!F4:F503),0)) | G33: =IFERROR(IF(C33="","",IF(E33=0,"",F33/E33)),"") | H33: =IF(C33="","",IF(F33=0,"—",IF(G33>=1,"✅ TERCAPAI",IF(G33>=0.5,"⚠ MENUJU TARGET","❌ BELUM TERCAPAI")))) | I33: =IFERROR(IF(C33="","",SUM(E5:E33)),"") | J33: =IFERROR(IF(C33="","",SUM(F5:F33)),"") | K33: =IFERROR(IF(C33="","",IF(I33=0,"",J33/I33)),"") | L33: =IFERROR(IF(C33="","",I33-J33),"")
B34: 30 | C34: =IFERROR(IF(30>'MASTER DATA'!I2,"",DATE('MASTER DATA'!F2,'MASTER DATA'!D2,30)),"") | D34: =IF(C34="","",TEXT(C34,"DDDD")) | E34: =IF(C34="","",IFERROR(SUM('MASTER DATA'!J5:J19),0)) | F34: =IF(C34="","",IFERROR(SUMIF('INPUT HARIAN'!C4:C503,C34,'INPUT HARIAN'!F4:F503),0)) | G34: =IFERROR(IF(C34="","",IF(E34=0,"",F34/E34)),"") | H34: =IF(C34="","",IF(F34=0,"—",IF(G34>=1,"✅ TERCAPAI",IF(G34>=0.5,"⚠ MENUJU TARGET","❌ BELUM TERCAPAI")))) | I34: =IFERROR(IF(C34="","",SUM(E5:E34)),"") | J34: =IFERROR(IF(C34="","",SUM(F5:F34)),"") | K34: =IFERROR(IF(C34="","",IF(I34=0,"",J34/I34)),"") | L34: =IFERROR(IF(C34="","",I34-J34),"")
B35: 31 | C35: =IFERROR(IF(31>'MASTER DATA'!I2,"",DATE('MASTER DATA'!F2,'MASTER DATA'!D2,31)),"") | D35: =IF(C35="","",TEXT(C35,"DDDD")) | E35: =IF(C35="","",IFERROR(SUM('MASTER DATA'!J5:J19),0)) | F35: =IF(C35="","",IFERROR(SUMIF('INPUT HARIAN'!C4:C503,C35,'INPUT HARIAN'!F4:F503),0)) | G35: =IFERROR(IF(C35="","",IF(E35=0,"",F35/E35)),"") | H35: =IF(C35="","",IF(F35=0,"—",IF(G35>=1,"✅ TERCAPAI",IF(G35>=0.5,"⚠ MENUJU TARGET","❌ BELUM TERCAPAI")))) | I35: =IFERROR(IF(C35="","",SUM(E5:E35)),"") | J35: =IFERROR(IF(C35="","",SUM(F5:F35)),"") | K35: =IFERROR(IF(C35="","",IF(I35=0,"",J35/I35)),"") | L35: =IFERROR(IF(C35="","",I35-J35),"")
B36: TOTAL BULAN | E36: =IFERROR(SUM(E5:E35),"") | F36: =IFERROR(SUM(F5:F35),"") | G36: =IFERROR(F36/E36,"")
B38: 👥 REKAP HARIAN — USER / PESERTA
B39: No | C39: Tanggal | D39: Hari | E39: Target Harian | F39: Pencapaian Harian | G39: % Harian | H39: Status | I39: Kumulatif Target | J39: Kumulatif Capaian | K39: % Kumulatif | L39: Gap Kumulatif
B40: 1 | C40: =IFERROR(IF(1>'MASTER DATA'!I2,"",DATE('MASTER DATA'!F2,'MASTER DATA'!D2,1)),"") | D40: =IF(C40="","",TEXT(C40,"DDDD")) | E40: =IF(C40="","",IFERROR(SUM('MASTER DATA'!K5:K19),0)) | F40: =IF(C40="","",IFERROR(SUMIF('INPUT HARIAN'!C4:C503,C40,'INPUT HARIAN'!G4:G503),0)) | G40: =IFERROR(IF(C40="","",IF(E40=0,"",F40/E40)),"") | H40: =IF(C40="","",IF(F40=0,"—",IF(G40>=1,"✅ TERCAPAI",IF(G40>=0.5,"⚠ MENUJU TARGET","❌ BELUM TERCAPAI")))) | I40: =IFERROR(IF(C40="","",SUM(E40)),"") | J40: =IFERROR(IF(C40="","",SUM(F40)),"") | K40: =IFERROR(IF(C40="","",IF(I40=0,"",J40/I40)),"") | L40: =IFERROR(IF(C40="","",I40-J40),"")
B41: 2 | C41: =IFERROR(IF(2>'MASTER DATA'!I2,"",DATE('MASTER DATA'!F2,'MASTER DATA'!D2,2)),"") | D41: =IF(C41="","",TEXT(C41,"DDDD")) | E41: =IF(C41="","",IFERROR(SUM('MASTER DATA'!K5:K19),0)) | F41: =IF(C41="","",IFERROR(SUMIF('INPUT HARIAN'!C4:C503,C41,'INPUT HARIAN'!G4:G503),0)) | G41: =IFERROR(IF(C41="","",IF(E41=0,"",F41/E41)),"") | H41: =IF(C41="","",IF(F41=0,"—",IF(G41>=1,"✅ TERCAPAI",IF(G41>=0.5,"⚠ MENUJU TARGET","❌ BELUM TERCAPAI")))) | I41: =IFERROR(IF(C41="","",SUM(E40:E41)),"") | J41: =IFERROR(IF(C41="","",SUM(F40:F41)),"") | K41: =IFERROR(IF(C41="","",IF(I41=0,"",J41/I41)),"") | L41: =IFERROR(IF(C41="","",I41-J41),"")
...

Sheet DASHBOARD HARIAN PROGRAM
B1: 📋 DASHBOARD HARIAN PER PROGRAM — APRIL 2026 | P1: 46118
B2: Data pencapaian diambil otomatis dari INPUT HARIAN. Tambah program baru: isi di sheet MASTER DATA baris 20 dst. 🔵 Biru = input manual | ⬛ = formula otomatis
B4: 📊 RINGKASAN TARGET & PENCAPAIAN PER PROGRAM — RUPIAH (Rp) | Q4: 📌 RINGKASAN HARI INI
B5: No | C5: Program | D5: PIC | E5: Target Harian (Rp) | F5: Pencapaian Hari Ini (Rp) | G5: % Harian | H5: Status Harian | I5: Capaian Bulan Ini (Rp) | J5: Target Bulanan (Rp) | K5: % Bulanan | L5: Sisa Target (Rp) | M5: Progress Bar | N5: Target Harian (User) | O5: Capaian Hari (User) | Q5: Tanggal Aktif | R5: =TEXT(P1,"DD MMMM YYYY")
B6: ='MASTER DATA'!B5 | C6: ='MASTER DATA'!C5 | D6: ='MASTER DATA'!D5 | E6: =IF('MASTER DATA'!C5="","",'MASTER DATA'!J5) | F6: =IF('MASTER DATA'!C5="","",SUMIFS('INPUT HARIAN'!F4:F503,'INPUT HARIAN'!D4:D503,'MASTER DATA'!C5,'INPUT HARIAN'!C4:C503,P1)) | G6: =IF(OR('MASTER DATA'!C5="",E6="",E6=0),"",F6/E6) | H6: =IF('MASTER DATA'!C5="","",IF(G6="","—",IF(G6>=1,"✅ TERCAPAI",IF(G6>=0.5,"⚠️ MENDEKATI","❌ PERLU PERHATIAN")))) | I6: =IF('MASTER DATA'!C5="","",SUMIFS('INPUT HARIAN'!F4:F503,'INPUT HARIAN'!D4:D503,'MASTER DATA'!C5,'INPUT HARIAN'!C4:C503,">="&DATE(YEAR(P1),MONTH(P1),1),'INPUT HARIAN'!C4:C503,"<="&EOMONTH(P1,0))) | J6: =IF('MASTER DATA'!C5="","",'MASTER DATA'!E5) | K6: =IF(OR('MASTER DATA'!C5="",J6="",J6=0),"",I6/J6) | L6: =IF(OR('MASTER DATA'!C5="",J6=""),"",J6-I6) | M6: =IF(OR('MASTER DATA'!C5="",K6=""),"",REPT("█",MIN(INT(K6*20),20))&" "&TEXT(K6,"0.0%")) | N6: =IF('MASTER DATA'!C5="","",'MASTER DATA'!K5) | O6: =IF('MASTER DATA'!C5="","",SUMIFS('INPUT HARIAN'!G4:G503,'INPUT HARIAN'!D4:D503,'MASTER DATA'!C5,'INPUT HARIAN'!C4:C503,P1)) | Q6: Total Target Harian (Rp) | R6: =SUMIF(E6:E20,"<>")
B7: ='MASTER DATA'!B6 | C7: ='MASTER DATA'!C6 | D7: ='MASTER DATA'!D6 | E7: =IF('MASTER DATA'!C6="","",'MASTER DATA'!J6) | F7: =IF('MASTER DATA'!C6="","",SUMIFS('INPUT HARIAN'!F4:F503,'INPUT HARIAN'!D4:D503,'MASTER DATA'!C6,'INPUT HARIAN'!C4:C503,P1)) | G7: =IF(OR('MASTER DATA'!C6="",E7="",E7=0),"",F7/E7) | H7: =IF('MASTER DATA'!C6="","",IF(G7="","—",IF(G7>=1,"✅ TERCAPAI",IF(G7>=0.5,"⚠️ MENDEKATI","❌ PERLU PERHATIAN")))) | I7: =IF('MASTER DATA'!C6="","",SUMIFS('INPUT HARIAN'!F4:F503,'INPUT HARIAN'!D4:D503,'MASTER DATA'!C6,'INPUT HARIAN'!C4:C503,">="&DATE(YEAR(P1),MONTH(P1),1),'INPUT HARIAN'!C4:C503,"<="&EOMONTH(P1,0))) | J7: =IF('MASTER DATA'!C6="","",'MASTER DATA'!E6) | K7: =IF(OR('MASTER DATA'!C6="",J7="",J7=0),"",I7/J7) | L7: =IF(OR('MASTER DATA'!C6="",J7=""),"",J7-I7) | M7: =IF(OR('MASTER DATA'!C6="",K7=""),"",REPT("█",MIN(INT(K7*20),20))&" "&TEXT(K7,"0.0%")) | N7: =IF('MASTER DATA'!C6="","",'MASTER DATA'!K6) | O7: =IF('MASTER DATA'!C6="","",SUMIFS('INPUT HARIAN'!G4:G503,'INPUT HARIAN'!D4:D503,'MASTER DATA'!C6,'INPUT HARIAN'!C4:C503,P1)) | Q7: Total Capaian Hari Ini (Rp) | R7: =SUMIF(F6:F20,"<>")
B8: ='MASTER DATA'!B7 | C8: ='MASTER DATA'!C7 | D8: ='MASTER DATA'!D7 | E8: =IF('MASTER DATA'!C7="","",'MASTER DATA'!J7) | F8: =IF('MASTER DATA'!C7="","",SUMIFS('INPUT HARIAN'!F4:F503,'INPUT HARIAN'!D4:D503,'MASTER DATA'!C7,'INPUT HARIAN'!C4:C503,P1)) | G8: =IF(OR('MASTER DATA'!C7="",E8="",E8=0),"",F8/E8) | H8: =IF('MASTER DATA'!C7="","",IF(G8="","—",IF(G8>=1,"✅ TERCAPAI",IF(G8>=0.5,"⚠️ MENDEKATI","❌ PERLU PERHATIAN")))) | I8: =IF('MASTER DATA'!C7="","",SUMIFS('INPUT HARIAN'!F4:F503,'INPUT HARIAN'!D4:D503,'MASTER DATA'!C7,'INPUT HARIAN'!C4:C503,">="&DATE(YEAR(P1),MONTH(P1),1),'INPUT HARIAN'!C4:C503,"<="&EOMONTH(P1,0))) | J8: =IF('MASTER DATA'!C7="","",'MASTER DATA'!E7) | K8: =IF(OR('MASTER DATA'!C7="",J8="",J8=0),"",I8/J8) | L8: =IF(OR('MASTER DATA'!C7="",J8=""),"",J8-I8) | M8: =IF(OR('MASTER DATA'!C7="",K8=""),"",REPT("█",MIN(INT(K8*20),20))&" "&TEXT(K8,"0.0%")) | N8: =IF('MASTER DATA'!C7="","",'MASTER DATA'!K7) | O8: =IF('MASTER DATA'!C7="","",SUMIFS('INPUT HARIAN'!G4:G503,'INPUT HARIAN'!D4:D503,'MASTER DATA'!C7,'INPUT HARIAN'!C4:C503,P1)) | Q8: % Pencapaian Harian | R8: =IF(R6=0,"",R7/R6)
B9: ='MASTER DATA'!B8 | C9: ='MASTER DATA'!C8 | D9: ='MASTER DATA'!D8 | E9: =IF('MASTER DATA'!C8="","",'MASTER DATA'!J8) | F9: =IF('MASTER DATA'!C8="","",SUMIFS('INPUT HARIAN'!F4:F503,'INPUT HARIAN'!D4:D503,'MASTER DATA'!C8,'INPUT HARIAN'!C4:C503,P1)) | G9: =IF(OR('MASTER DATA'!C8="",E9="",E9=0),"",F9/E9) | H9: =IF('MASTER DATA'!C8="","",IF(G9="","—",IF(G9>=1,"✅ TERCAPAI",IF(G9>=0.5,"⚠️ MENDEKATI","❌ PERLU PERHATIAN")))) | I9: =IF('MASTER DATA'!C8="","",SUMIFS('INPUT HARIAN'!F4:F503,'INPUT HARIAN'!D4:D503,'MASTER DATA'!C8,'INPUT HARIAN'!C4:C503,">="&DATE(YEAR(P1),MONTH(P1),1),'INPUT HARIAN'!C4:C503,"<="&EOMONTH(P1,0))) | J9: =IF('MASTER DATA'!C8="","",'MASTER DATA'!E8) | K9: =IF(OR('MASTER DATA'!C8="",J9="",J9=0),"",I9/J9) | L9: =IF(OR('MASTER DATA'!C8="",J9=""),"",J9-I9) | M9: =IF(OR('MASTER DATA'!C8="",K9=""),"",REPT("█",MIN(INT(K9*20),20))&" "&TEXT(K9,"0.0%")) | N9: =IF('MASTER DATA'!C8="","",'MASTER DATA'!K8) | O9: =IF('MASTER DATA'!C8="","",SUMIFS('INPUT HARIAN'!G4:G503,'INPUT HARIAN'!D4:D503,'MASTER DATA'!C8,'INPUT HARIAN'!C4:C503,P1)) | Q9: Target Bulanan (Rp) | R9: =SUMIF(J6:J20,"<>")
B10: ='MASTER DATA'!B9 | C10: ='MASTER DATA'!C9 | D10: ='MASTER DATA'!D9 | E10: =IF('MASTER DATA'!C9="","",'MASTER DATA'!J9) | F10: =IF('MASTER DATA'!C9="","",SUMIFS('INPUT HARIAN'!F4:F503,'INPUT HARIAN'!D4:D503,'MASTER DATA'!C9,'INPUT HARIAN'!C4:C503,P1)) | G10: =IF(OR('MASTER DATA'!C9="",E10="",E10=0),"",F10/E10) | H10: =IF('MASTER DATA'!C9="","",IF(G10="","—",IF(G10>=1,"✅ TERCAPAI",IF(G10>=0.5,"⚠️ MENDEKATI","❌ PERLU PERHATIAN")))) | I10: =IF('MASTER DATA'!C9="","",SUMIFS('INPUT HARIAN'!F4:F503,'INPUT HARIAN'!D4:D503,'MASTER DATA'!C9,'INPUT HARIAN'!C4:C503,">="&DATE(YEAR(P1),MONTH(P1),1),'INPUT HARIAN'!C4:C503,"<="&EOMONTH(P1,0))) | J10: =IF('MASTER DATA'!C9="","",'MASTER DATA'!E9) | K10: =IF(OR('MASTER DATA'!C9="",J10="",J10=0),"",I10/J10) | L10: =IF(OR('MASTER DATA'!C9="",J10=""),"",J10-I10) | M10: =IF(OR('MASTER DATA'!C9="",K10=""),"",REPT("█",MIN(INT(K10*20),20))&" "&TEXT(K10,"0.0%")) | N10: =IF('MASTER DATA'!C9="","",'MASTER DATA'!K9) | O10: =IF('MASTER DATA'!C9="","",SUMIFS('INPUT HARIAN'!G4:G503,'INPUT HARIAN'!D4:D503,'MASTER DATA'!C9,'INPUT HARIAN'!C4:C503,P1)) | Q10: Capaian Bulan Ini (Rp) | R10: =SUMIF(I6:I20,"<>")
B11: ='MASTER DATA'!B10 | C11: ='MASTER DATA'!C10 | D11: ='MASTER DATA'!D10 | E11: =IF('MASTER DATA'!C10="","",'MASTER DATA'!J10) | F11: =IF('MASTER DATA'!C10="","",SUMIFS('INPUT HARIAN'!F4:F503,'INPUT HARIAN'!D4:D503,'MASTER DATA'!C10,'INPUT HARIAN'!C4:C503,P1)) | G11: =IF(OR('MASTER DATA'!C10="",E11="",E11=0),"",F11/E11) | H11: =IF('MASTER DATA'!C10="","",IF(G11="","—",IF(G11>=1,"✅ TERCAPAI",IF(G11>=0.5,"⚠️ MENDEKATI","❌ PERLU PERHATIAN")))) | I11: =IF('MASTER DATA'!C10="","",SUMIFS('INPUT HARIAN'!F4:F503,'INPUT HARIAN'!D4:D503,'MASTER DATA'!C10,'INPUT HARIAN'!C4:C503,">="&DATE(YEAR(P1),MONTH(P1),1),'INPUT HARIAN'!C4:C503,"<="&EOMONTH(P1,0))) | J11: =IF('MASTER DATA'!C10="","",'MASTER DATA'!E10) | K11: =IF(OR('MASTER DATA'!C10="",J11="",J11=0),"",I11/J11) | L11: =IF(OR('MASTER DATA'!C10="",J11=""),"",J11-I11) | M11: =IF(OR('MASTER DATA'!C10="",K11=""),"",REPT("█",MIN(INT(K11*20),20))&" "&TEXT(K11,"0.0%")) | N11: =IF('MASTER DATA'!C10="","",'MASTER DATA'!K10) | O11: =IF('MASTER DATA'!C10="","",SUMIFS('INPUT HARIAN'!G4:G503,'INPUT HARIAN'!D4:D503,'MASTER DATA'!C10,'INPUT HARIAN'!C4:C503,P1)) | Q11: % Capaian Bulanan | R11: =IF(R9=0,"",R10/R9)
B12: ='MASTER DATA'!B11 | C12: ='MASTER DATA'!C11 | D12: ='MASTER DATA'!D11 | E12: =IF('MASTER DATA'!C11="","",'MASTER DATA'!J11) | F12: =IF('MASTER DATA'!C11="","",SUMIFS('INPUT HARIAN'!F4:F503,'INPUT HARIAN'!D4:D503,'MASTER DATA'!C11,'INPUT HARIAN'!C4:C503,P1)) | G12: =IF(OR('MASTER DATA'!C11="",E12="",E12=0),"",F12/E12) | H12: =IF('MASTER DATA'!C11="","",IF(G12="","—",IF(G12>=1,"✅ TERCAPAI",IF(G12>=0.5,"⚠️ MENDEKATI","❌ PERLU PERHATIAN")))) | I12: =IF('MASTER DATA'!C11="","",SUMIFS('INPUT HARIAN'!F4:F503,'INPUT HARIAN'!D4:D503,'MASTER DATA'!C11,'INPUT HARIAN'!C4:C503,">="&DATE(YEAR(P1),MONTH(P1),1),'INPUT HARIAN'!C4:C503,"<="&EOMONTH(P1,0))) | J12: =IF('MASTER DATA'!C11="","",'MASTER DATA'!E11) | K12: =IF(OR('MASTER DATA'!C11="",J12="",J12=0),"",I12/J12) | L12: =IF(OR('MASTER DATA'!C11="",J12=""),"",J12-I12) | M12: =IF(OR('MASTER DATA'!C11="",K12=""),"",REPT("█",MIN(INT(K12*20),20))&" "&TEXT(K12,"0.0%")) | N12: =IF('MASTER DATA'!C11="","",'MASTER DATA'!K11) | O12: =IF('MASTER DATA'!C11="","",SUMIFS('INPUT HARIAN'!G4:G503,'INPUT HARIAN'!D4:D503,'MASTER DATA'!C11,'INPUT HARIAN'!C4:C503,P1)) | Q12: Jumlah Program Aktif | R12: =COUNTIF('MASTER DATA'!C5:C19,"<>")
B13: ='MASTER DATA'!B12 | C13: ='MASTER DATA'!C12 | D13: ='MASTER DATA'!D12 | E13: =IF('MASTER DATA'!C12="","",'MASTER DATA'!J12) | F13: =IF('MASTER DATA'!C12="","",SUMIFS('INPUT HARIAN'!F4:F503,'INPUT HARIAN'!D4:D503,'MASTER DATA'!C12,'INPUT HARIAN'!C4:C503,P1)) | G13: =IF(OR('MASTER DATA'!C12="",E13="",E13=0),"",F13/E13) | H13: =IF('MASTER DATA'!C12="","",IF(G13="","—",IF(G13>=1,"✅ TERCAPAI",IF(G13>=0.5,"⚠️ MENDEKATI","❌ PERLU PERHATIAN")))) | I13: =IF('MASTER DATA'!C12="","",SUMIFS('INPUT HARIAN'!F4:F503,'INPUT HARIAN'!D4:D503,'MASTER DATA'!C12,'INPUT HARIAN'!C4:C503,">="&DATE(YEAR(P1),MONTH(P1),1),'INPUT HARIAN'!C4:C503,"<="&EOMONTH(P1,0))) | J13: =IF('MASTER DATA'!C12="","",'MASTER DATA'!E12) | K13: =IF(OR('MASTER DATA'!C12="",J13="",J13=0),"",I13/J13) | L13: =IF(OR('MASTER DATA'!C12="",J13=""),"",J13-I13) | M13: =IF(OR('MASTER DATA'!C12="",K13=""),"",REPT("█",MIN(INT(K13*20),20))&" "&TEXT(K13,"0.0%")) | N13: =IF('MASTER DATA'!C12="","",'MASTER DATA'!K12) | O13: =IF('MASTER DATA'!C12="","",SUMIFS('INPUT HARIAN'!G4:G503,'INPUT HARIAN'!D4:D503,'MASTER DATA'!C12,'INPUT HARIAN'!C4:C503,P1)) | Q13: Program Tercapai Hari Ini | R13: =COUNTIF(G6:G20,">="&1)
B14: ='MASTER DATA'!B13 | C14: ='MASTER DATA'!C13 | D14: ='MASTER DATA'!D13 | E14: =IF('MASTER DATA'!C13="","",'MASTER DATA'!J13) | F14: =IF('MASTER DATA'!C13="","",SUMIFS('INPUT HARIAN'!F4:F503,'INPUT HARIAN'!D4:D503,'MASTER DATA'!C13,'INPUT HARIAN'!C4:C503,P1)) | G14: =IF(OR('MASTER DATA'!C13="",E14="",E14=0),"",F14/E14) | H14: =IF('MASTER DATA'!C13="","",IF(G14="","—",IF(G14>=1,"✅ TERCAPAI",IF(G14>=0.5,"⚠️ MENDEKATI","❌ PERLU PERHATIAN")))) | I14: =IF('MASTER DATA'!C13="","",SUMIFS('INPUT HARIAN'!F4:F503,'INPUT HARIAN'!D4:D503,'MASTER DATA'!C13,'INPUT HARIAN'!C4:C503,">="&DATE(YEAR(P1),MONTH(P1),1),'INPUT HARIAN'!C4:C503,"<="&EOMONTH(P1,0))) | J14: =IF('MASTER DATA'!C13="","",'MASTER DATA'!E13) | K14: =IF(OR('MASTER DATA'!C13="",J14="",J14=0),"",I14/J14) | L14: =IF(OR('MASTER DATA'!C13="",J14=""),"",J14-I14) | M14: =IF(OR('MASTER DATA'!C13="",K14=""),"",REPT("█",MIN(INT(K14*20),20))&" "&TEXT(K14,"0.0%")) | N14: =IF('MASTER DATA'!C13="","",'MASTER DATA'!K13) | O14: =IF('MASTER DATA'!C13="","",SUMIFS('INPUT HARIAN'!G4:G503,'INPUT HARIAN'!D4:D503,'MASTER DATA'!C13,'INPUT HARIAN'!C4:C503,P1)) | Q14: Program Belum Tercapai | R14: =COUNTIF(G6:G20,"<1")-COUNTBLANK(G6:G20)
B15: ='MASTER DATA'!B14 | C15: ='MASTER DATA'!C14 | D15: ='MASTER DATA'!D14 | E15: =IF('MASTER DATA'!C14="","",'MASTER DATA'!J14) | F15: =IF('MASTER DATA'!C14="","",SUMIFS('INPUT HARIAN'!F4:F503,'INPUT HARIAN'!D4:D503,'MASTER DATA'!C14,'INPUT HARIAN'!C4:C503,P1)) | G15: =IF(OR('MASTER DATA'!C14="",E15="",E15=0),"",F15/E15) | H15: =IF('MASTER DATA'!C14="","",IF(G15="","—",IF(G15>=1,"✅ TERCAPAI",IF(G15>=0.5,"⚠️ MENDEKATI","❌ PERLU PERHATIAN")))) | I15: =IF('MASTER DATA'!C14="","",SUMIFS('INPUT HARIAN'!F4:F503,'INPUT HARIAN'!D4:D503,'MASTER DATA'!C14,'INPUT HARIAN'!C4:C503,">="&DATE(YEAR(P1),MONTH(P1),1),'INPUT HARIAN'!C4:C503,"<="&EOMONTH(P1,0))) | J15: =IF('MASTER DATA'!C14="","",'MASTER DATA'!E14) | K15: =IF(OR('MASTER DATA'!C14="",J15="",J15=0),"",I15/J15) | L15: =IF(OR('MASTER DATA'!C14="",J15=""),"",J15-I15) | M15: =IF(OR('MASTER DATA'!C14="",K15=""),"",REPT("█",MIN(INT(K15*20),20))&" "&TEXT(K15,"0.0%")) | N15: =IF('MASTER DATA'!C14="","",'MASTER DATA'!K14) | O15: =IF('MASTER DATA'!C14="","",SUMIFS('INPUT HARIAN'!G4:G503,'INPUT HARIAN'!D4:D503,'MASTER DATA'!C14,'INPUT HARIAN'!C4:C503,P1))
B16: ='MASTER DATA'!B15 | C16: ='MASTER DATA'!C15 | D16: ='MASTER DATA'!D15 | E16: =IF('MASTER DATA'!C15="","",'MASTER DATA'!J15) | F16: =IF('MASTER DATA'!C15="","",SUMIFS('INPUT HARIAN'!F4:F503,'INPUT HARIAN'!D4:D503,'MASTER DATA'!C15,'INPUT HARIAN'!C4:C503,P1)) | G16: =IF(OR('MASTER DATA'!C15="",E16="",E16=0),"",F16/E16) | H16: =IF('MASTER DATA'!C15="","",IF(G16="","—",IF(G16>=1,"✅ TERCAPAI",IF(G16>=0.5,"⚠️ MENDEKATI","❌ PERLU PERHATIAN")))) | I16: =IF('MASTER DATA'!C15="","",SUMIFS('INPUT HARIAN'!F4:F503,'INPUT HARIAN'!D4:D503,'MASTER DATA'!C15,'INPUT HARIAN'!C4:C503,">="&DATE(YEAR(P1),MONTH(P1),1),'INPUT HARIAN'!C4:C503,"<="&EOMONTH(P1,0))) | J16: =IF('MASTER DATA'!C15="","",'MASTER DATA'!E15) | K16: =IF(OR('MASTER DATA'!C15="",J16="",J16=0),"",I16/J16) | L16: =IF(OR('MASTER DATA'!C15="",J16=""),"",J16-I16) | M16: =IF(OR('MASTER DATA'!C15="",K16=""),"",REPT("█",MIN(INT(K16*20),20))&" "&TEXT(K16,"0.0%")) | N16: =IF('MASTER DATA'!C15="","",'MASTER DATA'!K15) | O16: =IF('MASTER DATA'!C15="","",SUMIFS('INPUT HARIAN'!G4:G503,'INPUT HARIAN'!D4:D503,'MASTER DATA'!C15,'INPUT HARIAN'!C4:C503,P1))
B17: ='MASTER DATA'!B16 | C17: ='MASTER DATA'!C16 | D17: ='MASTER DATA'!D16 | E17: =IF('MASTER DATA'!C16="","",'MASTER DATA'!J16) | F17: =IF('MASTER DATA'!C16="","",SUMIFS('INPUT HARIAN'!F4:F503,'INPUT HARIAN'!D4:D503,'MASTER DATA'!C16,'INPUT HARIAN'!C4:C503,P1)) | G17: =IF(OR('MASTER DATA'!C16="",E17="",E17=0),"",F17/E17) | H17: =IF('MASTER DATA'!C16="","",IF(G17="","—",IF(G17>=1,"✅ TERCAPAI",IF(G17>=0.5,"⚠️ MENDEKATI","❌ PERLU PERHATIAN")))) | I17: =IF('MASTER DATA'!C16="","",SUMIFS('INPUT HARIAN'!F4:F503,'INPUT HARIAN'!D4:D503,'MASTER DATA'!C16,'INPUT HARIAN'!C4:C503,">="&DATE(YEAR(P1),MONTH(P1),1),'INPUT HARIAN'!C4:C503,"<="&EOMONTH(P1,0))) | J17: =IF('MASTER DATA'!C16="","",'MASTER DATA'!E16) | K17: =IF(OR('MASTER DATA'!C16="",J17="",J17=0),"",I17/J17) | L17: =IF(OR('MASTER DATA'!C16="",J17=""),"",J17-I17) | M17: =IF(OR('MASTER DATA'!C16="",K17=""),"",REPT("█",MIN(INT(K17*20),20))&" "&TEXT(K17,"0.0%")) | N17: =IF('MASTER DATA'!C16="","",'MASTER DATA'!K16) | O17: =IF('MASTER DATA'!C16="","",SUMIFS('INPUT HARIAN'!G4:G503,'INPUT HARIAN'!D4:D503,'MASTER DATA'!C16,'INPUT HARIAN'!C4:C503,P1))
